Workbook
Name NOMBRE_ASIGNATURA: DATOS!$A$2
Name Unidad1: DATOS!$I$5
Name Unidad10: DATOS!$I$14
Name Unidad11: DATOS!$I$15
Name Unidad12: DATOS!$I$16
Name Unidad13: DATOS!$I$17
Name Unidad14: DATOS!$I$18
Name Unidad15: DATOS!$I$19
Name Unidad2: DATOS!$I$6
Name Unidad3: DATOS!$I$7
Name Unidad4: DATOS!$I$8
Name Unidad5: DATOS!$I$9
Name Unidad6: DATOS!$I$10
Name Unidad7: DATOS!$I$11
Name Unidad8: DATOS!$I$12
Name Unidad9: DATOS!$I$13

Sheet finalV1
A2: U1. El átomo y los enlaces | B2: CE1 | H2: CE2 | N2: CE3 | T2: CE4 | Z2: CE5 | AF2: CE6
A3: =DATOS!A2 -> CCGG 2º BTO | B3: CR1.1 | C3: CR1.2 | D3: CR1.3 | E3: CR1.4 | F3: CR1.5 | G3: CR1.6 | H3: CR2.1 | I3: CR2.2 | J3: CR2.3 | K3: CR2.4 | L3: CR2.5 | M3: CR2.6 | N3: CR3.1 | O3: CR3.2 | P3: CR3.3 | Q3: CR3.4 | R3: CR3.5 | S3: CR3.6 | T3: CR4.1 | U3: CR4.2 | V3: CR4.3 | W3: CR4.4 | X3: CR4.5 | Y3: CR4.6 | Z3: CR5.1 | AA3: CR5.2 | AB3: CR5.3 | AC3: CR5.4 | AD3: CR5.5 | AE3: CR5.6 | AF3: CR6.1 | AG3: CR6.2 | AH3: CR6.3 | AI3: CR6.4 | AJ3: CR6.5 | AK3: CR6.6
A4: =DATOS!B5 -> Garcia, Ana
A5: =DATOS!B6 -> Martinez carlos
A6: =DATOS!B7 -> Sanchez Laura
A7: =DATOS!B8 -> Lopez Diego
A8: =DATOS!B9 -> Gonzalez Torres, Mara�a
A9: =DATOS!B10 -> Rodra�guez Jimaanez, Pablo
A10: =DATOS!B11 -> Hernandez Moreno, Sofa�a
A11: =DATOS!B12 -> Da�az Castro, Alejandro
A12: =DATOS!B13 -> a�lvarez Romero, Elena
A13: =DATOS!B14 -> Mua�oz Navarro, Javier
A14: =DATOS!B15 -> Romero Gil, Claudia
A15: =DATOS!B16 -> Alonso Serrano, Marcos
... A40: =DATOS!B41 -> 0

Sheet notas
A3: notas
A4: actualizado el formato en la evaluacion2 que no modificaba el formato en la recuperacion
A5: modificado el resultado final en la evaluaciones.que no tenia en cuenta el maximo entre la nota y la recuperacon( si que la tenia en cuenta en el resultado de las competencias, pero no en la nota final)

Sheet 1ª EVA
A1: =NOMBRE_ASIGNATURA -> CCGG 2º BTO
A3: 1ª EVALUACIÓN | B3: CEspecíf.1 | O3: CEspecíf.2 | AB3: CEspecíf.3 | AO3: CEspecíf.4 | BB3: CEspecíf.5 | BO3: CEspecíf.6 | CB3: Resumen | CC3: SB | CD3: SUMA PESOS TOTALES
B4: =PESOS!B4 -> Inst ev. | C4: =PESOS!C4 -> CR1.1 | E4: =PESOS!D4 -> CR1.2 | G4: =PESOS!E4 -> CR1.3 | I4: =PESOS!F4 -> CR1.4 | K4: =PESOS!G4 -> CR1.5 | M4: =PESOS!H4 -> CR1.6 | O4: =PESOS!I4 -> Inst ev | P4: =PESOS!J4 -> CR2.1 | R4: =PESOS!K4 -> CR2.2 | T4: =PESOS!L4 -> CR2.3 | V4: =PESOS!M4 -> CR2.4 | X4: =PESOS!N4 -> CR2.5 | Z4: =PESOS!O4 -> CR2.6 | AB4: =PESOS!P4 -> Inst ev. | AC4: =PESOS!Q4 -> CR3.1 | AE4: =PESOS!R4 -> CR3.2 | AG4: =PESOS!S4 -> CR3.3 | AI4: =PESOS!T4 -> CR3.4 | AK4: =PESOS!U4 -> CR3.5 | AM4: =PESOS!V4 -> CR3.6 | AO4: =PESOS!W4 -> Inst ev. | AP4: =PESOS!X4 -> CR4.1 | AR4: =PESOS!Y4 -> CR4.2 | AT4: =PESOS!Z4 -> CR4.3 | AV4: =PESOS!AA4 -> CR4.4 | AX4: =PESOS!AB4 -> CR4.5 | AZ4: =PESOS!AC4 -> CR4.6 | BB4: =PESOS!AD4 -> Inst ev. | BC4: =PESOS!AE4 -> CR5.1 | BE4: =PESOS!AF4 -> CR5.2 | BG4: =PESOS!AG4 -> CR5.3 | BI4: =PESOS!AH4 -> CR5.4 | BK4: =PESOS!AI4 -> CR5.5 | BM4: =PESOS!AJ4 -> CR5.6 | BO4: =PESOS!AK4 -> Inst ev. | BP4: =PESOS!AL4 -> CR6.1 | BR4: =PESOS!AM4 -> CR6.2 | BT4: =PESOS!AN4 -> CR6.3 | BV4: =PESOS!AO4 -> CR6.4 | BX4: =PESOS!AP4 -> CR6.5 | BZ4: =PESOS!AQ4 -> CR6.6 | CB4: =PESOS!AR4
A5: {=IFERROR(INDEX(UNIDADES1EVA[UNIDADES 1ª], ROW(A1)), "")} -> U1. El átomo y los enlaces | B5: {=IFERROR(VLOOKUP($A5,PESOS!$A:$AZ,COLUMN(B:B),FALSE),"")} -> TD | C5: {=IFERROR(VLOOKUP($A5,PESOS!$A:$AZ,COLUMN(C:C),FALSE),"")} -> 5 | E5: {=IFERROR(VLOOKUP($A5,PESOS!$A:$AZ,COLUMN(D:D),FALSE),"")} -> 5 | G5: {=IFERROR(VLOOKUP($A5,PESOS!$A:$AZ,COLUMN(E:E),FALSE),"")} -> 5 | I5: {=IFERROR(VLOOKUP($A5,PESOS!$A:$AZ,COLUMN(F:F),FALSE),"")} -> 5 | K5: {=IFERROR(VLOOKUP($A5,PESOS!$A:$AZ,COLUMN(G:G),FALSE),"")} -> 5 | M5: {=IFERROR(VLOOKUP($A5,PESOS!$A:$AZ,COLUMN(H:H),FALSE),"")} -> 0 | O5: {=IFERROR(VLOOKUP($A5,PESOS!$A:$AZ,COLUMN(I:I),FALSE),"")} -> 0 | P5: {=IFERROR(VLOOKUP($A5,PESOS!$A:$AZ,COLUMN(J:J),FALSE),"")} -> 5 | R5: {=IFERROR(VLOOKUP($A5,PESOS!$A:$AZ,COLUMN(K:K),FALSE),"")} -> 10 | T5: {=IFERROR(VLOOKUP($A5,PESOS!$A:$AZ,COLUMN(L:L),FALSE),"")} -> 10 | V5: {=IFERROR(VLOOKUP($A5,PESOS!$A:$AZ,COLUMN(M:M),FALSE),"")} -> 10 | X5: {=IFERROR(VLOOKUP($A5,PESOS!$A:$AZ,COLUMN(N:N),FALSE),"")} -> 0 | Z5: {=IFERROR(VLOOKUP($A5,PESOS!$A:$AZ,COLUMN(O:O),FALSE),"")} -> 0 | AB5: {=IFERROR(VLOOKUP($A5,PESOS!$A:$AZ,COLUMN(P:P),FALSE),"")} -> 0 | AC5: {=IFERROR(VLOOKUP($A5,PESOS!$A:$AZ,COLUMN(Q:Q),FALSE),"")} -> 0 | AE5: {=IFERROR(VLOOKUP($A5,PESOS!$A:$AZ,COLUMN(R:R),FALSE),"")} -> 0 | AG5: {=IFERROR(VLOOKUP($A5,PESOS!$A:$AZ,COLUMN(S:S),FALSE),"")} -> 0 | AI5: {=IFERROR(VLOOKUP($A5,PESOS!$A:$AZ,COLUMN(T:T),FALSE),"")} -> 5 | AK5: {=IFERROR(VLOOKUP($A5,PESOS!$A:$AZ,COLUMN(U:U),FALSE),"")} -> 5 | AM5: {=IFERROR(VLOOKUP($A5,PESOS!$A:$AZ,COLUMN(V:V),FALSE),"")} -> 0 | AO5: {=IFERROR(VLOOKUP($A5,PESOS!$A:$AZ,COLUMN(W:W),FALSE),"")} -> 0 | AP5: {=IFERROR(VLOOKUP($A5,PESOS!$A:$AZ,COLUMN(X:X),FALSE),"")} -> 5 | AR5: {=IFERROR(VLOOKUP($A5,PESOS!$A:$AZ,COLUMN(Y:Y),FALSE),"")} -> 5 | AT5: {=IFERROR(VLOOKUP($A5,PESOS!$A:$AZ,COLUMN(Z:Z),FALSE),"")} -> 0 | AV5: {=IFERROR(VLOOKUP($A5,PESOS!$A:$AZ,COLUMN(AA:AA),FALSE),"")} -> 5 | AX5: {=IFERROR(VLOOKUP($A5,PESOS!$A:$AZ,COLUMN(AB:AB),FALSE),"")} -> 0 | AZ5: {=IFERROR(VLOOKUP($A5,PESOS!$A:$AZ,COLUMN(AC:AC),FALSE),"")} -> 0 | BB5: {=IFERROR(VLOOKUP($A5,PESOS!$A:$AZ,COLUMN(AD:AD),FALSE),"")} -> 0 | BC5: {=IFERROR(VLOOKUP($A5,PESOS!$A:$AZ,COLUMN(AE:AE),FALSE),"")} -> 0 | BE5: {=IFERROR(VLOOKUP($A5,PESOS!$A:$AZ,COLUMN(AF:AF),FALSE),"")} -> 0 | BG5: {=IFERROR(VLOOKUP($A5,PESOS!$A:$AZ,COLUMN(AG:AG),FALSE),"")} -> 0 | BI5: {=IFERROR(VLOOKUP($A5,PESOS!$A:$AZ,COLUMN(AH:AH),FALSE),"")} -> 15 | BK5: {=IFERROR(VLOOKUP($A5,PESOS!$A:$AZ,COLUMN(AI:AI),FALSE),"")} -> 0 | BM5: {=IFERROR(VLOOKUP($A5,PESOS!$A:$AZ,COLUMN(AJ:AJ),FALSE),"")} -> 0 | BO5: {=IFERROR(VLOOKUP($A5,PESOS!$A:$AZ,COLUMN(AK:AK),FALSE),"")} -> 0 | BP5: {=IFERROR(VLOOKUP($A5,PESOS!$A:$AZ,COLUMN(AL:AL),FALSE),"")} -> 0 | BR5: {=IFERROR(VLOOKUP($A5,PESOS!$A:$AZ,COLUMN(AM:AM),FALSE),"")} -> 0 | BT5: {=IFERROR(VLOOKUP($A5,PESOS!$A:$AZ,COLUMN(AN:AN),FALSE),"")} -> 0 | BV5: {=IFERROR(VLOOKUP($A5,PESOS!$A:$AZ,COLUMN(AO:AO),FALSE),"")} -> 0 | BX5: {=IFERROR(VLOOKUP($A5,PESOS!$A:$AZ,COLUMN(AP:AP),FALSE),"")} -> 0 | BZ5: {=IFERROR(VLOOKUP($A5,PESOS!$A:$AZ,COLUMN(AQ:AQ),FALSE),"")} -> 0 | CB5: =SUM(C5:CA5) -> 100 | CC5: B | CD5: =SUM(CB5:CB10) -> 100
A6: {=IFERROR(INDEX(UNIDADES1EVA[UNIDADES 1ª], ROW(A2)), "")} -> 0 | B6: {=IFERROR(VLOOKUP($A6,PESOS!$A:$AZ,COLUMN(B:B),FALSE),"")} -> 0 | C6: {=IFERROR(VLOOKUP($A6,PESOS!$A:$AZ,COLUMN(C:C),FALSE),"")} -> 0 | E6: {=IFERROR(VLOOKUP($A6,PESOS!$A:$AZ,COLUMN(D:D),FALSE),"")} -> 0 | G6: {=IFERROR(VLOOKUP($A6,PESOS!$A:$AZ,COLUMN(E:E),FALSE),"")} -> 0 | I6: {=IFERROR(VLOOKUP($A6,PESOS!$A:$AZ,COLUMN(F:F),FALSE),"")} -> 0 | K6: {=IFERROR(VLOOKUP($A6,PESOS!$A:$AZ,COLUMN(G:G),FALSE),"")} -> 0 | M6: {=IFERROR(VLOOKUP($A6,PESOS!$A:$AZ,COLUMN(H:H),FALSE),"")} -> 0 | O6: {=IFERROR(VLOOKUP($A6,PESOS!$A:$AZ,COLUMN(I:I),FALSE),"")} -> 0 | P6: {=IFERROR(VLOOKUP($A6,PESOS!$A:$AZ,COLUMN(J:J),FALSE),"")} -> 0 | R6: {=IFERROR(VLOOKUP($A6,PESOS!$A:$AZ,COLUMN(K:K),FALSE),"")} -> 0 | T6: {=IFERROR(VLOOKUP($A6,PESOS!$A:$AZ,COLUMN(L:L),FALSE),"")} -> 0 | V6: {=IFERROR(VLOOKUP($A6,PESOS!$A:$AZ,COLUMN(M:M),FALSE),"")} -> 0 | X6: {=IFERROR(VLOOKUP($A6,PESOS!$A:$AZ,COLUMN(N:N),FALSE),"")} -> 0 | Z6: {=IFERROR(VLOOKUP($A6,PESOS!$A:$AZ,COLUMN(O:O),FALSE),"")} -> 0 | AB6: {=IFERROR(VLOOKUP($A6,PESOS!$A:$AZ,COLUMN(P:P),FALSE),"")} -> 0 | AC6: {=IFERROR(VLOOKUP($A6,PESOS!$A:$AZ,COLUMN(Q:Q),FALSE),"")} -> 0 | AE6: {=IFERROR(VLOOKUP($A6,PESOS!$A:$AZ,COLUMN(R:R),FALSE),"")} -> 0 | AG6: {=IFERROR(VLOOKUP($A6,PESOS!$A:$AZ,COLUMN(S:S),FALSE),"")} -> 0 | AI6: {=IFERROR(VLOOKUP($A6,PESOS!$A:$AZ,COLUMN(T:T),FALSE),"")} -> 0 | AK6: {=IFERROR(VLOOKUP($A6,PESOS!$A:$AZ,COLUMN(U:U),FALSE),"")} -> 0 | AM6: {=IFERROR(VLOOKUP($A6,PESOS!$A:$AZ,COLUMN(V:V),FALSE),"")} -> 0 | AO6: {=IFERROR(VLOOKUP($A6,PESOS!$A:$AZ,COLUMN(W:W),FALSE),"")} -> 0 | AP6: {=IFERROR(VLOOKUP($A6,PESOS!$A:$AZ,COLUMN(X:X),FALSE),"")} -> 0 | AR6: {=IFERROR(VLOOKUP($A6,PESOS!$A:$AZ,COLUMN(Y:Y),FALSE),"")} -> 0 | AT6: {=IFERROR(VLOOKUP($A6,PESOS!$A:$AZ,COLUMN(Z:Z),FALSE),"")} -> 0 | AV6: {=IFERROR(VLOOKUP($A6,PESOS!$A:$AZ,COLUMN(AA:AA),FALSE),"")} -> 0 | AX6: {=IFERROR(VLOOKUP($A6,PESOS!$A:$AZ,COLUMN(AB:AB),FALSE),"")} -> 0 | AZ6: {=IFERROR(VLOOKUP($A6,PESOS!$A:$AZ,COLUMN(AC:AC),FALSE),"")} -> 0 | BB6: {=IFERROR(VLOOKUP($A6,PESOS!$A:$AZ,COLUMN(AD:AD),FALSE),"")} -> 0 | BC6: {=IFERROR(VLOOKUP($A6,PESOS!$A:$AZ,COLUMN(AE:AE),FALSE),"")} -> 0 | BE6: {=IFERROR(VLOOKUP($A6,PESOS!$A:$AZ,COLUMN(AF:AF),FALSE),"")} -> 0 | BG6: {=IFERROR(VLOOKUP($A6,PESOS!$A:$AZ,COLUMN(AG:AG),FALSE),"")} -> 0 | BI6: {=IFERROR(VLOOKUP($A6,PESOS!$A:$AZ,COLUMN(AH:AH),FALSE),"")} -> 0 | BK6: {=IFERROR(VLOOKUP($A6,PESOS!$A:$AZ,COLUMN(AI:AI),FALSE),"")} -> 0 | BM6: {=IFERROR(VLOOKUP($A6,PESOS!$A:$AZ,COLUMN(AJ:AJ),FALSE),"")} -> 0 | BO6: {=IFERROR(VLOOKUP($A6,PESOS!$A:$AZ,COLUMN(AK:AK),FALSE),"")} -> 0 | BP6: {=IFERROR(VLOOKUP($A6,PESOS!$A:$AZ,COLUMN(AL:AL),FALSE),"")} -> 0 | BR6: {=IFERROR(VLOOKUP($A6,PESOS!$A:$AZ,COLUMN(AM:AM),FALSE),"")} -> 0 | BT6: {=IFERROR(VLOOKUP($A6,PESOS!$A:$AZ,COLUMN(AN:AN),FALSE),"")} -> 0 | BV6: {=IFERROR(VLOOKUP($A6,PESOS!$A:$AZ,COLUMN(AO:AO),FALSE),"")} -> 0 | BX6: {=IFERROR(VLOOKUP($A6,PESOS!$A:$AZ,COLUMN(AP:AP),FALSE),"")} -> 0 | BZ6: {=IFERROR(VLOOKUP($A6,PESOS!$A:$AZ,COLUMN(AQ:AQ),FALSE),"")} -> 0 | CB6: =SUM(C6:CA6) -> 0 | CC6: B
A7: {=IFERROR(INDEX(UNIDADES1EVA[UNIDADES 1ª], ROW(A3)), "")} -> 0 | B7: {=IFERROR(VLOOKUP($A7,PESOS!$A:$AZ,COLUMN(B:B),FALSE),"")} -> 0 | C7: {=IFERROR(VLOOKUP($A7,PESOS!$A:$AZ,COLUMN(C:C),FALSE),"")} -> 0 | E7: {=IFERROR(VLOOKUP($A7,PESOS!$A:$AZ,COLUMN(D:D),FALSE),"")} -> 0 | G7: {=IFERROR(VLOOKUP($A7,PESOS!$A:$AZ,COLUMN(E:E),FALSE),"")} -> 0 | I7: {=IFERROR(VLOOKUP($A7,PESOS!$A:$AZ,COLUMN(F:F),FALSE),"")} -> 0 | K7: {=IFERROR(VLOOKUP($A7,PESOS!$A:$AZ,COLUMN(G:G),FALSE),"")} -> 0 | M7: {=IFERROR(VLOOKUP($A7,PESOS!$A:$AZ,COLUMN(H:H),FALSE),"")} -> 0 | O7: {=IFERROR(VLOOKUP($A7,PESOS!$A:$AZ,COLUMN(I:I),FALSE),"")} -> 0 | P7: {=IFERROR(VLOOKUP($A7,PESOS!$A:$AZ,COLUMN(J:J),FALSE),"")} -> 0 | R7: {=IFERROR(VLOOKUP($A7,PESOS!$A:$AZ,COLUMN(K:K),FALSE),"")} -> 0 | T7: {=IFERROR(VLOOKUP($A7,PESOS!$A:$AZ,COLUMN(L:L),FALSE),"")} -> 0 | V7: {=IFERROR(VLOOKUP($A7,PESOS!$A:$AZ,COLUMN(M:M),FALSE),"")} -> 0 | X7: {=IFERROR(VLOOKUP($A7,PESOS!$A:$AZ,COLUMN(N:N),FALSE),"")} -> 0 | Z7: {=IFERROR(VLOOKUP($A7,PESOS!$A:$AZ,COLUMN(O:O),FALSE),"")} -> 0 | AB7: {=IFERROR(VLOOKUP($A7,PESOS!$A:$AZ,COLUMN(P:P),FALSE),"")} -> 0 | AC7: {=IFERROR(VLOOKUP($A7,PESOS!$A:$AZ,COLUMN(Q:Q),FALSE),"")} -> 0 | AE7: {=IFERROR(VLOOKUP($A7,PESOS!$A:$AZ,COLUMN(R:R),FALSE),"")} -> 0 | AG7: {=IFERROR(VLOOKUP($A7,PESOS!$A:$AZ,COLUMN(S:S),FALSE),"")} -> 0 | AI7: {=IFERROR(VLOOKUP($A7,PESOS!$A:$AZ,COLUMN(T:T),FALSE),"")} -> 0 | AK7: {=IFERROR(VLOOKUP($A7,PESOS!$A:$AZ,COLUMN(U:U),FALSE),"")} -> 0 | AM7: {=IFERROR(VLOOKUP($A7,PESOS!$A:$AZ,COLUMN(V:V),FALSE),"")} -> 0 | AO7: {=IFERROR(VLOOKUP($A7,PESOS!$A:$AZ,COLUMN(W:W),FALSE),"")} -> 0 | AP7: {=IFERROR(VLOOKUP($A7,PESOS!$A:$AZ,COLUMN(X:X),FALSE),"")} -> 0 | AR7: {=IFERROR(VLOOKUP($A7,PESOS!$A:$AZ,COLUMN(Y:Y),FALSE),"")} -> 0 | AT7: {=IFERROR(VLOOKUP($A7,PESOS!$A:$AZ,COLUMN(Z:Z),FALSE),"")} -> 0 | AV7: {=IFERROR(VLOOKUP($A7,PESOS!$A:$AZ,COLUMN(AA:AA),FALSE),"")} -> 0 | AX7: {=IFERROR(VLOOKUP($A7,PESOS!$A:$AZ,COLUMN(AB:AB),FALSE),"")} -> 0 | AZ7: {=IFERROR(VLOOKUP($A7,PESOS!$A:$AZ,COLUMN(AC:AC),FALSE),"")} -> 0 | BB7: {=IFERROR(VLOOKUP($A7,PESOS!$A:$AZ,COLUMN(AD:AD),FALSE),"")} -> 0 | BC7: {=IFERROR(VLOOKUP($A7,PESOS!$A:$AZ,COLUMN(AE:AE),FALSE),"")} -> 0 | BE7: {=IFERROR(VLOOKUP($A7,PESOS!$A:$AZ,COLUMN(AF:AF),FALSE),"")} -> 0 | BG7: {=IFERROR(VLOOKUP($A7,PESOS!$A:$AZ,COLUMN(AG:AG),FALSE),"")} -> 0 | BI7: {=IFERROR(VLOOKUP($A7,PESOS!$A:$AZ,COLUMN(AH:AH),FALSE),"")} -> 0 | BK7: {=IFERROR(VLOOKUP($A7,PESOS!$A:$AZ,COLUMN(AI:AI),FALSE),"")} -> 0 | BM7: {=IFERROR(VLOOKUP($A7,PESOS!$A:$AZ,COLUMN(AJ:AJ),FALSE),"")} -> 0 | BO7: {=IFERROR(VLOOKUP($A7,PESOS!$A:$AZ,COLUMN(AK:AK),FALSE),"")} -> 0 | BP7: {=IFERROR(VLOOKUP($A7,PESOS!$A:$AZ,COLUMN(AL:AL),FALSE),"")} -> 0 | BR7: {=IFERROR(VLOOKUP($A7,PESOS!$A:$AZ,COLUMN(AM:AM),FALSE),"")} -> 0 | BT7: {=IFERROR(VLOOKUP($A7,PESOS!$A:$AZ,COLUMN(AN:AN),FALSE),"")} -> 0 | BV7: {=IFERROR(VLOOKUP($A7,PESOS!$A:$AZ,COLUMN(AO:AO),FALSE),"")} -> 0 | BX7: {=IFERROR(VLOOKUP($A7,PESOS!$A:$AZ,COLUMN(AP:AP),FALSE),"")} -> 0 | BZ7: {=IFERROR(VLOOKUP($A7,PESOS!$A:$AZ,COLUMN(AQ:AQ),FALSE),"")} -> 0 | CB7: =SUM(C7:CA7) -> 0 | CC7: B
A8: {=IFERROR(INDEX(UNIDADES1EVA[UNIDADES 1ª], ROW(A4)), "")} -> 0 | B8: {=IFERROR(VLOOKUP($A8,PESOS!$A:$AZ,COLUMN(B:B),FALSE),"")} -> 0 | C8: {=IFERROR(VLOOKUP($A8,PESOS!$A:$AZ,COLUMN(C:C),FALSE),"")} -> 0 | E8: {=IFERROR(VLOOKUP($A8,PESOS!$A:$AZ,COLUMN(D:D),FALSE),"")} -> 0 | G8: {=IFERROR(VLOOKUP($A8,PESOS!$A:$AZ,COLUMN(E:E),FALSE),"")} -> 0 | I8: {=IFERROR(VLOOKUP($A8,PESOS!$A:$AZ,COLUMN(F:F),FALSE),"")} -> 0 | K8: {=IFERROR(VLOOKUP($A8,PESOS!$A:$AZ,COLUMN(G:G),FALSE),"")} -> 0 | M8: {=IFERROR(VLOOKUP($A8,PESOS!$A:$AZ,COLUMN(H:H),FALSE),"")} -> 0 | O8: {=IFERROR(VLOOKUP($A8,PESOS!$A:$AZ,COLUMN(I:I),FALSE),"")} -> 0 | P8: {=IFERROR(VLOOKUP($A8,PESOS!$A:$AZ,COLUMN(J:J),FALSE),"")} -> 0 | R8: {=IFERROR(VLOOKUP($A8,PESOS!$A:$AZ,COLUMN(K:K),FALSE),"")} -> 0 | T8: {=IFERROR(VLOOKUP($A8,PESOS!$A:$AZ,COLUMN(L:L),FALSE),"")} -> 0 | V8: {=IFERROR(VLOOKUP($A8,PESOS!$A:$AZ,COLUMN(M:M),FALSE),"")} -> 0 | X8: {=IFERROR(VLOOKUP($A8,PESOS!$A:$AZ,COLUMN(N:N),FALSE),"")} -> 0 | Z8: {=IFERROR(VLOOKUP($A8,PESOS!$A:$AZ,COLUMN(O:O),FALSE),"")} -> 0 | AB8: {=IFERROR(VLOOKUP($A8,PESOS!$A:$AZ,COLUMN(P:P),FALSE),"")} -> 0 | AC8: {=IFERROR(VLOOKUP($A8,PESOS!$A:$AZ,COLUMN(Q:Q),FALSE),"")} -> 0 | AE8: {=IFERROR(VLOOKUP($A8,PESOS!$A:$AZ,COLUMN(R:R),FALSE),"")} -> 0 | AG8: {=IFERROR(VLOOKUP($A8,PESOS!$A:$AZ,COLUMN(S:S),FALSE),"")} -> 0 | AI8: {=IFERROR(VLOOKUP($A8,PESOS!$A:$AZ,COLUMN(T:T),FALSE),"")} -> 0 | AK8: {=IFERROR(VLOOKUP($A8,PESOS!$A:$AZ,COLUMN(U:U),FALSE),"")} -> 0 | AM8: {=IFERROR(VLOOKUP($A8,PESOS!$A:$AZ,COLUMN(V:V),FALSE),"")} -> 0 | AO8: {=IFERROR(VLOOKUP($A8,PESOS!$A:$AZ,COLUMN(W:W),FALSE),"")} -> 0 | AP8: {=IFERROR(VLOOKUP($A8,PESOS!$A:$AZ,COLUMN(X:X),FALSE),"")} -> 0 | AR8: {=IFERROR(VLOOKUP($A8,PESOS!$A:$AZ,COLUMN(Y:Y),FALSE),"")} -> 0 | AT8: {=IFERROR(VLOOKUP($A8,PESOS!$A:$AZ,COLUMN(Z:Z),FALSE),"")} -> 0 | AV8: {=IFERROR(VLOOKUP($A8,PESOS!$A:$AZ,COLUMN(AA:AA),FALSE),"")} -> 0 | AX8: {=IFERROR(VLOOKUP($A8,PESOS!$A:$AZ,COLUMN(AB:AB),FALSE),"")} -> 0 | AZ8: {=IFERROR(VLOOKUP($A8,PESOS!$A:$AZ,COLUMN(AC:AC),FALSE),"")} -> 0 | BB8: {=IFERROR(VLOOKUP($A8,PESOS!$A:$AZ,COLUMN(AD:AD),FALSE),"")} -> 0 | BC8: {=IFERROR(VLOOKUP($A8,PESOS!$A:$AZ,COLUMN(AE:AE),FALSE),"")} -> 0 | BE8: {=IFERROR(VLOOKUP($A8,PESOS!$A:$AZ,COLUMN(AF:AF),FALSE),"")} -> 0 | BG8: {=IFERROR(VLOOKUP($A8,PESOS!$A:$AZ,COLUMN(AG:AG),FALSE),"")} -> 0 | BI8: {=IFERROR(VLOOKUP($A8,PESOS!$A:$AZ,COLUMN(AH:AH),FALSE),"")} -> 0 | BK8: {=IFERROR(VLOOKUP($A8,PESOS!$A:$AZ,COLUMN(AI:AI),FALSE),"")} -> 0 | BM8: {=IFERROR(VLOOKUP($A8,PESOS!$A:$AZ,COLUMN(AJ:AJ),FALSE),"")} -> 0 | BO8: {=IFERROR(VLOOKUP($A8,PESOS!$A:$AZ,COLUMN(AK:AK),FALSE),"")} -> 0 | BP8: {=IFERROR(VLOOKUP($A8,PESOS!$A:$AZ,COLUMN(AL:AL),FALSE),"")} -> 0 | BR8: {=IFERROR(VLOOKUP($A8,PESOS!$A:$AZ,COLUMN(AM:AM),FALSE),"")} -> 0 | BT8: {=IFERROR(VLOOKUP($A8,PESOS!$A:$AZ,COLUMN(AN:AN),FALSE),"")} -> 0 | BV8: {=IFERROR(VLOOKUP($A8,PESOS!$A:$AZ,COLUMN(AO:AO),FALSE),"")} -> 0 | BX8: {=IFERROR(VLOOKUP($A8,PESOS!$A:$AZ,COLUMN(AP:AP),FALSE),"")} -> 0 | BZ8: {=IFERROR(VLOOKUP($A8,PESOS!$A:$AZ,COLUMN(AQ:AQ),FALSE),"")} -> 0 | CB8: =SUM(C8:CA8) -> 0 | CC8: C
A9: {=IFERROR(INDEX(UNIDADES1EVA[UNIDADES 1ª], ROW(A5)), "")} -> 0 | B9: {=IFERROR(VLOOKUP($A9,PESOS!$A:$AZ,COLUMN(B:B),FALSE),"")} -> 0 | C9: {=IFERROR(VLOOKUP($A9,PESOS!$A:$AZ,COLUMN(C:C),FALSE),"")} -> 0 | E9: {=IFERROR(VLOOKUP($A9,PESOS!$A:$AZ,COLUMN(D:D),FALSE),"")} -> 0 | G9: {=IFERROR(VLOOKUP($A9,PESOS!$A:$AZ,COLUMN(E:E),FALSE),"")} -> 0 | I9: {=IFERROR(VLOOKUP($A9,PESOS!$A:$AZ,COLUMN(F:F),FALSE),"")} -> 0 | K9: {=IFERROR(VLOOKUP($A9,PESOS!$A:$AZ,COLUMN(G:G),FALSE),"")} -> 0 | M9: {=IFERROR(VLOOKUP($A9,PESOS!$A:$AZ,COLUMN(H:H),FALSE),"")} -> 0 | O9: {=IFERROR(VLOOKUP($A9,PESOS!$A:$AZ,COLUMN(I:I),FALSE),"")} -> 0 | P9: {=IFERROR(VLOOKUP($A9,PESOS!$A:$AZ,COLUMN(J:J),FALSE),"")} -> 0 | R9: {=IFERROR(VLOOKUP($A9,PESOS!$A:$AZ,COLUMN(K:K),FALSE),"")} -> 0 | T9: {=IFERROR(VLOOKUP($A9,PESOS!$A:$AZ,COLUMN(L:L),FALSE),"")} -> 0 | V9: {=IFERROR(VLOOKUP($A9,PESOS!$A:$AZ,COLUMN(M:M),FALSE),"")} -> 0 | X9: {=IFERROR(VLOOKUP($A9,PESOS!$A:$AZ,COLUMN(N:N),FALSE),"")} -> 0 | Z9: {=IFERROR(VLOOKUP($A9,PESOS!$A:$AZ,COLUMN(O:O),FALSE),"")} -> 0 | AB9: {=IFERROR(VLOOKUP($A9,PESOS!$A:$AZ,COLUMN(P:P),FALSE),"")} -> 0 | AC9: {=IFERROR(VLOOKUP($A9,PESOS!$A:$AZ,COLUMN(Q:Q),FALSE),"")} -> 0 | AE9: {=IFERROR(VLOOKUP($A9,PESOS!$A:$AZ,COLUMN(R:R),FALSE),"")} -> 0 | AG9: {=IFERROR(VLOOKUP($A9,PESOS!$A:$AZ,COLUMN(S:S),FALSE),"")} -> 0 | AI9: {=IFERROR(VLOOKUP($A9,PESOS!$A:$AZ,COLUMN(T:T),FALSE),"")} -> 0 | AK9: {=IFERROR(VLOOKUP($A9,PESOS!$A:$AZ,COLUMN(U:U),FALSE),"")} -> 0 | AM9: {=IFERROR(VLOOKUP($A9,PESOS!$A:$AZ,COLUMN(V:V),FALSE),"")} -> 0 | AO9: {=IFERROR(VLOOKUP($A9,PESOS!$A:$AZ,COLUMN(W:W),FALSE),"")} -> 0 | AP9: {=IFERROR(VLOOKUP($A9,PESOS!$A:$AZ,COLUMN(X:X),FALSE),"")} -> 0 | AR9: {=IFERROR(VLOOKUP($A9,PESOS!$A:$AZ,COLUMN(Y:Y),FALSE),"")} -> 0 | AT9: {=IFERROR(VLOOKUP($A9,PESOS!$A:$AZ,COLUMN(Z:Z),FALSE),"")} -> 0 | AV9: {=IFERROR(VLOOKUP($A9,PESOS!$A:$AZ,COLUMN(AA:AA),FALSE),"")} -> 0 | AX9: {=IFERROR(VLOOKUP($A9,PESOS!$A:$AZ,COLUMN(AB:AB),FALSE),"")} -> 0 | AZ9: {=IFERROR(VLOOKUP($A9,PESOS!$A:$AZ,COLUMN(AC:AC),FALSE),"")} -> 0 | BB9: {=IFERROR(VLOOKUP($A9,PESOS!$A:$AZ,COLUMN(AD:AD),FALSE),"")} -> 0 | BC9: {=IFERROR(VLOOKUP($A9,PESOS!$A:$AZ,COLUMN(AE:AE),FALSE),"")} -> 0 | BE9: {=IFERROR(VLOOKUP($A9,PESOS!$A:$AZ,COLUMN(AF:AF),FALSE),"")} -> 0 | BG9: {=IFERROR(VLOOKUP($A9,PESOS!$A:$AZ,COLUMN(AG:AG),FALSE),"")} -> 0 | BI9: {=IFERROR(VLOOKUP($A9,PESOS!$A:$AZ,COLUMN(AH:AH),FALSE),"")} -> 0 | BK9: {=IFERROR(VLOOKUP($A9,PESOS!$A:$AZ,COLUMN(AI:AI),FALSE),"")} -> 0 | BM9: {=IFERROR(VLOOKUP($A9,PESOS!$A:$AZ,COLUMN(AJ:AJ),FALSE),"")} -> 0 | BO9: {=IFERROR(VLOOKUP($A9,PESOS!$A:$AZ,COLUMN(AK:AK),FALSE),"")} -> 0 | BP9: {=IFERROR(VLOOKUP($A9,PESOS!$A:$AZ,COLUMN(AL:AL),FALSE),"")} -> 0 | BR9: {=IFERROR(VLOOKUP($A9,PESOS!$A:$AZ,COLUMN(AM:AM),FALSE),"")} -> 0 | BT9: {=IFERROR(VLOOKUP($A9,PESOS!$A:$AZ,COLUMN(AN:AN),FALSE),"")} -> 0 | BV9: {=IFERROR(VLOOKUP($A9,PESOS!$A:$AZ,COLUMN(AO:AO),FALSE),"")} -> 0 | BX9: {=IFERROR(VLOOKUP($A9,PESOS!$A:$AZ,COLUMN(AP:AP),FALSE),"")} -> 0 | BZ9: {=IFERROR(VLOOKUP($A9,PESOS!$A:$AZ,COLUMN(AQ:AQ),FALSE),"")} -> 0 | CB9: =SUM(C9:CA9) -> 0
A10: {=IFERROR(INDEX(UNIDADES1EVA[UNIDADES 1ª], ROW(A6)), "")} -> 0 | B10: {=IFERROR(VLOOKUP($A10,PESOS!$A:$AZ,COLUMN(B:B),FALSE),"")} -> 0 | C10: {=IFERROR(VLOOKUP($A10,PESOS!$A:$AZ,COLUMN(C:C),FALSE),"")} -> 0 | E10: {=IFERROR(VLOOKUP($A10,PESOS!$A:$AZ,COLUMN(D:D),FALSE),"")} -> 0 | G10: {=IFERROR(VLOOKUP($A10,PESOS!$A:$AZ,COLUMN(E:E),FALSE),"")} -> 0 | I10: {=IFERROR(VLOOKUP($A10,PESOS!$A:$AZ,COLUMN(F:F),FALSE),"")} -> 0 | K10: {=IFERROR(VLOOKUP($A10,PESOS!$A:$AZ,COLUMN(G:G),FALSE),"")} -> 0 | M10: {=IFERROR(VLOOKUP($A10,PESOS!$A:$AZ,COLUMN(H:H),FALSE),"")} -> 0 | O10: {=IFERROR(VLOOKUP($A10,PESOS!$A:$AZ,COLUMN(I:I),FALSE),"")} -> 0 | P10: {=IFERROR(VLOOKUP($A10,PESOS!$A:$AZ,COLUMN(J:J),FALSE),"")} -> 0 | R10: {=IFERROR(VLOOKUP($A10,PESOS!$A:$AZ,COLUMN(K:K),FALSE),"")} -> 0 | T10: {=IFERROR(VLOOKUP($A10,PESOS!$A:$AZ,COLUMN(L:L),FALSE),"")} -> 0 | V10: {=IFERROR(VLOOKUP($A10,PESOS!$A:$AZ,COLUMN(M:M),FALSE),"")} -> 0 | X10: {=IFERROR(VLOOKUP($A10,PESOS!$A:$AZ,COLUMN(N:N),FALSE),"")} -> 0 | Z10: {=IFERROR(VLOOKUP($A10,PESOS!$A:$AZ,COLUMN(O:O),FALSE),"")} -> 0 | AB10: {=IFERROR(VLOOKUP($A10,PESOS!$A:$AZ,COLUMN(P:P),FALSE),"")} -> 0 | AC10: {=IFERROR(VLOOKUP($A10,PESOS!$A:$AZ,COLUMN(Q:Q),FALSE),"")} -> 0 | AE10: {=IFERROR(VLOOKUP($A10,PESOS!$A:$AZ,COLUMN(R:R),FALSE),"")} -> 0 | AG10: {=IFERROR(VLOOKUP($A10,PESOS!$A:$AZ,COLUMN(S:S),FALSE),"")} -> 0 | AI10: {=IFERROR(VLOOKUP($A10,PESOS!$A:$AZ,COLUMN(T:T),FALSE),"")} -> 0 | AK10: {=IFERROR(VLOOKUP($A10,PESOS!$A:$AZ,COLUMN(U:U),FALSE),"")} -> 0 | AM10: {=IFERROR(VLOOKUP($A10,PESOS!$A:$AZ,COLUMN(V:V),FALSE),"")} -> 0 | AO10: {=IFERROR(VLOOKUP($A10,PESOS!$A:$AZ,COLUMN(W:W),FALSE),"")} -> 0 | AP10: {=IFERROR(VLOOKUP($A10,PESOS!$A:$AZ,COLUMN(X:X),FALSE),"")} -> 0 | AR10: {=IFERROR(VLOOKUP($A10,PESOS!$A:$AZ,COLUMN(Y:Y),FALSE),"")} -> 0 | AT10: {=IFERROR(VLOOKUP($A10,PESOS!$A:$AZ,COLUMN(Z:Z),FALSE),"")} -> 0 | AV10: {=IFERROR(VLOOKUP($A10,PESOS!$A:$AZ,COLUMN(AA:AA),FALSE),"")} -> 0 | AX10: {=IFERROR(VLOOKUP($A10,PESOS!$A:$AZ,COLUMN(AB:AB),FALSE),"")} -> 0 | AZ10: {=IFERROR(VLOOKUP($A10,PESOS!$A:$AZ,COLUMN(AC:AC),FALSE),"")} -> 0 | BB10: {=IFERROR(VLOOKUP($A10,PESOS!$A:$AZ,COLUMN(AD:AD),FALSE),"")} -> 0 | BC10: {=IFERROR(VLOOKUP($A10,PESOS!$A:$AZ,COLUMN(AE:AE),FALSE),"")} -> 0 | BE10: {=IFERROR(VLOOKUP($A10,PESOS!$A:$AZ,COLUMN(AF:AF),FALSE),"")} -> 0 | BG10: {=IFERROR(VLOOKUP($A10,PESOS!$A:$AZ,COLUMN(AG:AG),FALSE),"")} -> 0 | BI10: {=IFERROR(VLOOKUP($A10,PESOS!$A:$AZ,COLUMN(AH:AH),FALSE),"")} -> 0 | BK10: {=IFERROR(VLOOKUP($A10,PESOS!$A:$AZ,COLUMN(AI:AI),FALSE),"")} -> 0 | BM10: {=IFERROR(VLOOKUP($A10,PESOS!$A:$AZ,COLUMN(AJ:AJ),FALSE),"")} -> 0 | BO10: {=IFERROR(VLOOKUP($A10,PESOS!$A:$AZ,COLUMN(AK:AK),FALSE),"")} -> 0 | BP10: {=IFERROR(VLOOKUP($A10,PESOS!$A:$AZ,COLUMN(AL:AL),FALSE),"")} -> 0 | BR10: {=IFERROR(VLOOKUP($A10,PESOS!$A:$AZ,COLUMN(AM:AM),FALSE),"")} -> 0 | BT10: {=IFERROR(VLOOKUP($A10,PESOS!$A:$AZ,COLUMN(AN:AN),FALSE),"")} -> 0 | BV10: {=IFERROR(VLOOKUP($A10,PESOS!$A:$AZ,COLUMN(AO:AO),FALSE),"")} -> 0 | BX10: {=IFERROR(VLOOKUP($A10,PESOS!$A:$AZ,COLUMN(AP:AP),FALSE),"")} -> 0 | BZ10: {=IFERROR(VLOOKUP($A10,PESOS!$A:$AZ,COLUMN(AQ:AQ),FALSE),"")} -> 0 | CB10: =SUM(C10:CA10) -> 0
A12: Suma Ponderacion por unidades del criterio | B12: X | C12: =SUM(C5:C10) -> 5 | E12: =SUM(E5:E10) -> 5 | G12: =SUM(G5:G10) -> 5 | I12: =SUM(I5:I10) -> 5 | K12: =SUM(K5:K10) -> 5 | M12: =SUM(M5:M10) -> 0 | O12: X | P12: =SUM(P5:P10) -> 5 | R12: =SUM(R5:R10) -> 10 | T12: =SUM(T5:T10) -> 10 | V12: =SUM(V5:V10) -> 10 | X12: =SUM(X5:X10) -> 0 | Z12: =SUM(Z5:Z10) -> 0 | AB12: X | AC12: =SUM(AC5:AC10) -> 0 | AE12: =SUM(AE5:AE10) -> 0 | AG12: =SUM(AG5:AG10) -> 0 | AI12: =SUM(AI5:AI10) -> 5 | AK12: =SUM(AK5:AK10) -> 5 | AM12: =SUM(AM5:AM10) -> 0 | AO12: X | AP12: =SUM(AP5:AP10) -> 5 | AR12: =SUM(AR5:AR10) -> 5 | AT12: =SUM(AT5:AT10) -> 0 | AV12: =SUM(AV5:AV10) -> 5 | AX12: =SUM(AX5:AX10) -> 0 | AZ12: =SUM(AZ5:AZ10) -> 0 | BB12: X | BC12: =SUM(BC5:BC10) -> 0 | BE12: =SUM(BE5:BE10) -> 0 | BG12: =SUM(BG5:BG10) -> 0 | BI12: =SUM(BI5:BI10) -> 15 | BK12: =SUM(BK5:BK10) -> 0 | BM12: =SUM(BM5:BM10) -> 0 | BO12: X | BP12: =SUM(BP5:BP10) -> 0 | BR12: =SUM(BR5:BR10) -> 0 | BT12: =SUM(BT5:BT10) -> 0 | BV12: =SUM(BV5:BV10) -> 0 | BX12: =SUM(BX5:BX10) -> 0 | BZ12: =SUM(BZ5:BZ10) -> 0 | CB12: =SUM(B12:BZ12) -> 100
A13: % MEDIA PONDERADA CRITERIO | C13: =IFERROR(C12/$CD$5,) -> 0.05 | E13: =IFERROR(E12/$CD$5,) -> 0.05 | G13: =IFERROR(G12/$CD$5,) -> 0.05 | I13: =IFERROR(I12/$CD$5,) -> 0.05 | K13: =IFERROR(K12/$CD$5,) -> 0.05 | M13: =IFERROR(M12/$CD$5,) -> 0 | P13: =IFERROR(P12/$CD$5,) -> 0.05 | R13: =IFERROR(R12/$CD$5,) -> 0.1 | T13: =IFERROR(T12/$CD$5,) -> 0.1 | V13: =IFERROR(V12/$CD$5,) -> 0.1 | X13: =IFERROR(X12/$CD$5,) -> 0 | Z13: =IFERROR(Z12/$CD$5,) -> 0 | AC13: =IFERROR(AC12/$CD$5,) -> 0 | AE13: =IFERROR(AE12/$CD$5,) -> 0 | AG13: =IFERROR(AG12/$CD$5,) -> 0 | AI13: =IFERROR(AI12/$CD$5,) -> 0.05 | AK13: =IFERROR(AK12/$CD$5,) -> 0.05 | AM13: =IFERROR(AM12/$CD$5,) -> 0 | AP13: =IFERROR(AP12/$CD$5,) -> 0.05 | AR13: =IFERROR(AR12/$CD$5,) -> 0.05 | AT13: =IFERROR(AT12/$CD$5,) -> 0 | AV13: =IFERROR(AV12/$CD$5,) -> 0.05 | AX13: =IFERROR(AX12/$CD$5,) -> 0 | AZ13: =IFERROR(AZ12/$CD$5,) -> 0 | BC13: =IFERROR(BC12/$CD$5,) -> 0 | BE13: =IFERROR(BE12/$CD$5,) -> 0 | BG13: =IFERROR(BG12/$CD$5,) -> 0 | BI13: =IFERROR(BI12/$CD$5,) -> 0.15 | BK13: =IFERROR(BK12/$CD$5,) -> 0 | BM13: =IFERROR(BM12/$CD$5,) -> 0 | BP13: =IFERROR(BP12/$CD$5,) -> 0 | BR13: =IFERROR(BR12/$CD$5,) -> 0 | BT13: =IFERROR(BT12/$CD$5,) -> 0 | BV13: =IFERROR(BV12/$CD$5,) -> 0 | BX13: =IFERROR(BX12/$CD$5,) -> 0 | BZ13: =IFERROR(BZ12/$CD$5,) -> 0 | CB13: =SUM(B13:BZ13) -> 1
A14: PESO DEL CRITERIO EN LA EVALUACIÓN | B14: =SUM(C13:M13) -> 0.25 | O14: =SUM(P13:Z13) -> 0.35 | AB14: =SUM(AC13:AM13) -> 0.1 | AO14: =SUM(AP13:AZ13) -> 0.15 | BB14: =SUM(BC13:BM13) -> 0.15 | BO14: =SUM(BP13:BZ13) -> 0 | CB14: =SUM(B14:BZ14) -> 1
B16: CEspecíf.1 | O16: CEspecíf.2 | AB16: CEspecíf.3 | AO16: CEspecíf.4 | BB16: CEspecíf.5 | BO16: CEspecíf.6 | CB16: NOTA FINAL
B17: NOTA CE | C17: CR1.1 | E17: CR1.2 | G17: CR1.3 | I17: CR1.4 | K17: CR1.5 | M17: CR1.6 | O17: NOTA CE | P17: CR2.1 | R17: CR2.2 | T17: CR2.3 | V17: CR2.4 | X17: CR2.5 | Z17: CR2.6 | AB17: NOTA CE | AC17: CR3.1 | AE17: CR3.2 | AG17: CR3.3 | AI17: CR3.4 | AK17: CR3.5 | AM17: CR3.6 | AO17: NOTA CE | AP17: CR4.1 | AR17: CR4.2 | AT17: CR4.3 | AV17: CR4.4 | AX17: CR4.5 | AZ17: CR4.6 | BB17: NOTA CE | BC17: CR5.1 | BE17: CR5.2 | BG17: CR5.3 | BI17: CR5.4 | BK17: CR5.5 | BM17: CR5.6 | BO17: NOTA CE | BP17: CR6.1 | BR17: CR6.2 | BT17: CR6.3 | BV17: CR6.4 | BX17: CR6.5 | BZ17: CR6.6
D18: Rec | F18: Rec | H18: Rec | J18: Rec | L18: Rec | N18: Rec | Q18: Rec | S18: Rec | U18: Rec | W18: Rec | Y18: Rec | AA18: Rec | AD18: Rec | AF18: Rec | AH18: Rec | AJ18: Rec | AL18: Rec | AN18: Rec | AQ18: Rec | AS18: Rec | AU18: Rec | AW18: Rec | AY18: Rec | BA18: Rec | BD18: Rec | BF18: Rec | BH18: Rec | BJ18: Rec | BL18: Rec | BN18: Rec | BQ18: Rec | BS18: Rec | BU18: Rec | BW18: Rec | BY18: Rec | CA18: Rec
A19: {=Alumnado[Alumnado]} -> Garcia, Ana | B19: =IFERROR(SUM( MAX(C19,D19)*C$13, MAX(E19,F19)*E$13, MAX(G19,H19)*G$13, MAX(I19,J19)*I$13, MAX(K19,L19)*K$13, MAX(M19,N19)*M$13 )/B$14,"") -> 0 | C19: =IF(C$13>0, ( ( IF('U1'!$A$4="1ª", 'U1'!B5*'U1'!B$4, 0) + IF('U2'!$A$4="1ª", 'U2'!B5*'U2'!B$4, 0) + IF('U3'!$A$4="1ª", 'U3'!B5*'U3'!B$4, 0) + IF('U4'!$A$4="1ª", 'U4'!B5*'U4'!B$4, 0) + IF('U5'!$A$4="1ª", 'U5'!B5*'U5'!B$4, 0) + IF('U6'!$A$4="1ª", 'U6'!B5*'U6'!B$4, 0) + IF('U7'!$A$4="1ª", 'U7'!B5*'U7'!B$4, 0) + IF('U8'!$A$4="1ª", 'U8'!B5*'U8'!B$4, 0) + IF('U9'!$A$4="1ª", 'U9'!B5*'U9'!B$4, 0) + IF('U10'!$A$4="1ª", 'U10'!B5*'U10'!B$4, 0) + IF('U11'!$A$4="1ª", 'U11'!B5*'U11'!B$4, 0) + IF('U12'!$A$4="1ª", 'U12'!B5*'U12'!B$4, 0) + IF('U13'!$A$4="1ª", 'U13'!B5*'U13'!B$4, 0) + IF('U14'!$A$4="1ª", 'U14'!B5*'U14'!B$4, 0) + IF('U15'!$A$4="1ª", 'U15'!B5*'U15'!B$4, 0) ) /$CB$12 ) /C$13, "") -> 0 | E19: =IF(E$13>0, ( ( IF('U1'!$A$4="1ª", 'U1'!C5*'U1'!C$4, 0) + IF('U2'!$A$4="1ª", 'U2'!C5*'U2'!C$4, 0) + IF('U3'!$A$4="1ª", 'U3'!C5*'U3'!C$4, 0) + IF('U4'!$A$4="1ª", 'U4'!C5*'U4'!C$4, 0) + IF('U5'!$A$4="1ª", 'U5'!C5*'U5'!C$4, 0) + IF('U6'!$A$4="1ª", 'U6'!C5*'U6'!C$4, 0) + IF('U7'!$A$4="1ª", 'U7'!C5*'U7'!C$4, 0) + IF('U8'!$A$4="1ª", 'U8'!C5*'U8'!C$4, 0) + IF('U9'!$A$4="1ª", 'U9'!C5*'U9'!C$4, 0) + IF('U10'!$A$4="1ª", 'U10'!C5*'U10'!C$4, 0) + IF('U11'!$A$4="1ª", 'U11'!C5*'U11'!C$4, 0) + IF('U12'!$A$4="1ª", 'U12'!C5*'U12'!C$4, 0) + IF('U13'!$A$4="1ª", 'U13'!C5*'U13'!C$4, 0) + IF('U14'!$A$4="1ª", 'U14'!C5*'U14'!C$4, 0) + IF('U15'!$A$4="1ª", 'U15'!C5*'U15'!C$4, 0) ) /$CB$12 ) /E$13, "") -> 0 | G19: =IF(G$13>0, ( ( IF('U1'!$A$4="1ª", 'U1'!D5*'U1'!D$4, 0) + IF('U2'!$A$4="1ª", 'U2'!D5*'U2'!D$4, 0) + IF('U3'!$A$4="1ª", 'U3'!D5*'U3'!D$4, 0) + IF('U4'!$A$4="1ª", 'U4'!D5*'U4'!D$4, 0) + IF('U5'!$A$4="1ª", 'U5'!D5*'U5'!D$4, 0) + IF('U6'!$A$4="1ª", 'U6'!D5*'U6'!D$4, 0) + IF('U7'!$A$4="1ª", 'U7'!D5*'U7'!D$4, 0) + IF('U8'!$A$4="1ª", 'U8'!D5*'U8'!D$4, 0) + IF('U9'!$A$4="1ª", 'U9'!D5*'U9'!D$4, 0) + IF('U10'!$A$4="1ª", 'U10'!D5*'U10'!D$4, 0) + IF('U11'!$A$4="1ª", 'U11'!D5*'U11'!D$4, 0) + IF('U12'!$A$4="1ª", 'U12'!D5*'U12'!D$4, 0) + IF('U13'!$A$4="1ª", 'U13'!D5*'U13'!D$4, 0) + IF('U14'!$A$4="1ª", 'U14'!D5*'U14'!D$4, 0) + IF('U15'!$A$4="1ª", 'U15'!D5*'U15'!D$4, 0) ) /$CB$12 ) /G$13, "") -> 0 | I19: =IF(I$13>0, ( ( IF('U1'!$A$4="1ª", 'U1'!E5*'U1'!E$4, 0) + IF('U2'!$A$4="1ª", 'U2'!E5*'U2'!E$4, 0) + IF('U3'!$A$4="1ª", 'U3'!E5*'U3'!E$4, 0) + IF('U4'!$A$4="1ª", 'U4'!E5*'U4'!E$4, 0) + IF('U5'!$A$4="1ª", 'U5'!E5*'U5'!E$4, 0) + IF('U6'!$A$4="1ª", 'U6'!E5*'U6'!E$4, 0) + IF('U7'!$A$4="1ª", 'U7'!E5*'U7'!E$4, 0) + IF('U8'!$A$4="1ª", 'U8'!E5*'U8'!E$4, 0) + IF('U9'!$A$4="1ª", 'U9'!E5*'U9'!E$4, 0) + IF('U10'!$A$4="1ª", 'U10'!E5*'U10'!E$4, 0) + IF('U11'!$A$4="1ª", 'U11'!E5*'U11'!E$4, 0) + IF('U12'!$A$4="1ª", 'U12'!E5*'U12'!E$4, 0) + IF('U13'!$A$4="1ª", 'U13'!E5*'U13'!E$4, 0) + IF('U14'!$A$4="1ª", 'U14'!E5*'U14'!E$4, 0) + IF('U15'!$A$4="1ª", 'U15'!E5*'U15'!E$4, 0) ) /$CB$12 ) /I$13, "") -> 0 | K19: =IF(K$13>0, ( ( IF('U1'!$A$4="1ª", 'U1'!F5*'U1'!F$4, 0) + IF('U2'!$A$4="1ª", 'U2'!F5*'U2'!F$4, 0) + IF('U3'!$A$4="1ª", 'U3'!F5*'U3'!F$4, 0) + IF('U4'!$A$4="1ª", 'U4'!F5*'U4'!F$4, 0) + IF('U5'!$A$4="1ª", 'U5'!F5*'U5'!F$4, 0) + IF('U6'!$A$4="1ª", 'U6'!F5*'U6'!F$4, 0) + IF('U7'!$A$4="1ª", 'U7'!F5*'U7'!F$4, 0) + IF('U8'!$A$4="1ª", 'U8'!F5*'U8'!F$4, 0) + IF('U9'!$A$4="1ª", 'U9'!F5*'U9'!F$4, 0) + IF('U10'!$A$4="1ª", 'U10'!F5*'U10'!F$4, 0) + IF('U11'!$A$4="1ª", 'U11'!F5*'U11'!F$4, 0) + IF('U12'!$A$4="1ª", 'U12'!F5*'U12'!F$4, 0) + IF('U13'!$A$4="1ª", 'U13'!F5*'U13'!F$4, 0) + IF('U14'!$A$4="1ª", 'U14'!F5*'U14'!F$4, 0) + IF('U15'!$A$4="1ª", 'U15'!F5*'U15'!F$4, 0) ) /$CB$12 ) /K$13, "") -> 0 | M19: =IF(M$13>0, ( ( IF('U1'!$A$4="1ª", 'U1'!G5*'U1'!G$4, 0) + IF('U2'!$A$4="1ª", 'U2'!G5*'U2'!G$4, 0) + IF('U3'!$A$4="1ª", 'U3'!G5*'U3'!G$4, 0) + IF('U4'!$A$4="1ª", 'U4'!G5*'U4'!G$4, 0) + IF('U5'!$A$4="1ª", 'U5'!G5*'U5'!G$4, 0) + IF('U6'!$A$4="1ª", 'U6'!G5*'U6'!G$4, 0) + IF('U7'!$A$4="1ª", 'U7'!G5*'U7'!G$4, 0) + IF('U8'!$A$4="1ª", 'U8'!G5*'U8'!G$4, 0) + IF('U9'!$A$4="1ª", 'U9'!G5*'U9'!G$4, 0) + IF('U10'!$A$4="1ª", 'U10'!G5*'U10'!G$4, 0) + IF('U11'!$A$4="1ª", 'U11'!G5*'U11'!G$4, 0) + IF('U12'!$A$4="1ª", 'U12'!G5*'U12'!G$4, 0) + IF('U13'!$A$4="1ª", 'U13'!G5*'U13'!G$4, 0) + IF('U14'!$A$4="1ª", 'U14'!G5*'U14'!G$4, 0) + IF('U15'!$A$4="1ª", 'U15'!G5*'U15'!G$4, 0) ) /$CB$12 ) /M$13, "0") -> 0 | O19: =IFERROR(SUM( MAX(P19,Q19)*P$13, MAX(R19,S19)*R$13, MAX(T19,U19)*T$13, MAX(V19,W19)*V$13, MAX(X19,Y19)*X$13, MAX(Z19,AA19)*Z$13 )/O$14,"") -> 0 | P19: =IF(P$13>0, ( ( IF('U1'!$A$4="1ª", 'U1'!H5*'U1'!H$4, 0) + IF('U2'!$A$4="1ª", 'U2'!H5*'U2'!H$4, 0) + IF('U3'!$A$4="1ª", 'U3'!H5*'U3'!H$4, 0) + IF('U4'!$A$4="1ª", 'U4'!H5*'U4'!H$4, 0) + IF('U5'!$A$4="1ª", 'U5'!H5*'U5'!H$4, 0) + IF('U6'!$A$4="1ª", 'U6'!H5*'U6'!H$4, 0) + IF('U7'!$A$4="1ª", 'U7'!H5*'U7'!H$4, 0) + IF('U8'!$A$4="1ª", 'U8'!H5*'U8'!H$4, 0) + IF('U9'!$A$4="1ª", 'U9'!H5*'U9'!H$4, 0) + IF('U10'!$A$4="1ª", 'U10'!H5*'U10'!H$4, 0) + IF('U11'!$A$4="1ª", 'U11'!H5*'U11'!H$4, 0) + IF('U12'!$A$4="1ª", 'U12'!H5*'U12'!H$4, 0) + IF('U13'!$A$4="1ª", 'U13'!H5*'U13'!H$4, 0) + IF('U14'!$A$4="1ª", 'U14'!H5*'U14'!H$4, 0) + IF('U15'!$A$4="1ª", 'U15'!H5*'U15'!H$4, 0) ) /$CB$12 ) /P$13, "") -> 0 | R19: =IF(R$13>0, ( ( IF('U1'!$A$4="1ª", 'U1'!I5*'U1'!I$4, 0) + IF('U2'!$A$4="1ª", 'U2'!I5*'U2'!I$4, 0) + IF('U3'!$A$4="1ª", 'U3'!I5*'U3'!I$4, 0) + IF('U4'!$A$4="1ª", 'U4'!I5*'U4'!I$4, 0) + IF('U5'!$A$4="1ª", 'U5'!I5*'U5'!I$4, 0) + IF('U6'!$A$4="1ª", 'U6'!I5*'U6'!I$4, 0) + IF('U7'!$A$4="1ª", 'U7'!I5*'U7'!I$4, 0) + IF('U8'!$A$4="1ª", 'U8'!I5*'U8'!I$4, 0) + IF('U9'!$A$4="1ª", 'U9'!I5*'U9'!I$4, 0) + IF('U10'!$A$4="1ª", 'U10'!I5*'U10'!I$4, 0) + IF('U11'!$A$4="1ª", 'U11'!I5*'U11'!I$4, 0) + IF('U12'!$A$4="1ª", 'U12'!I5*'U12'!I$4, 0) + IF('U13'!$A$4="1ª", 'U13'!I5*'U13'!I$4, 0) + IF('U14'!$A$4="1ª", 'U14'!I5*'U14'!I$4, 0) + IF('U15'!$A$4="1ª", 'U15'!I5*'U15'!I$4, 0) ) /$CB$12 ) /R$13, "") -> 0 | T19: =IF(T$13>0, ( ( IF('U1'!$A$4="1ª", 'U1'!J5*'U1'!J$4, 0) + IF('U2'!$A$4="1ª", 'U2'!J5*'U2'!J$4, 0) + IF('U3'!$A$4="1ª", 'U3'!J5*'U3'!J$4, 0) + IF('U4'!$A$4="1ª", 'U4'!J5*'U4'!J$4, 0) + IF('U5'!$A$4="1ª", 'U5'!J5*'U5'!J$4, 0) + IF('U6'!$A$4="1ª", 'U6'!J5*'U6'!J$4, 0) + IF('U7'!$A$4="1ª", 'U7'!J5*'U7'!J$4, 0) + IF('U8'!$A$4="1ª", 'U8'!J5*'U8'!J$4, 0) + IF('U9'!$A$4="1ª", 'U9'!J5*'U9'!J$4, 0) + IF('U10'!$A$4="1ª", 'U10'!J5*'U10'!J$4, 0) + IF('U11'!$A$4="1ª", 'U11'!J5*'U11'!J$4, 0) + IF('U12'!$A$4="1ª", 'U12'!J5*'U12'!J$4, 0) + IF('U13'!$A$4="1ª", 'U13'!J5*'U13'!J$4, 0) + IF('U14'!$A$4="1ª", 'U14'!J5*'U14'!J$4, 0) + IF('U15'!$A$4="1ª", 'U15'!J5*'U15'!J$4, 0) ) /$CB$12 ) /T$13, "") -> 0 | V19: =IF(V$13>0, ( ( IF('U1'!$A$4="1ª", 'U1'!K5*'U1'!K$4, 0) + IF('U2'!$A$4="1ª", 'U2'!K5*'U2'!K$4, 0) + IF('U3'!$A$4="1ª", 'U3'!K5*'U3'!K$4, 0) + IF('U4'!$A$4="1ª", 'U4'!K5*'U4'!K$4, 0) + IF('U5'!$A$4="1ª", 'U5'!K5*'U5'!K$4, 0) + IF('U6'!$A$4="1ª", 'U6'!K5*'U6'!K$4, 0) + IF('U7'!$A$4="1ª", 'U7'!K5*'U7'!K$4, 0) + IF('U8'!$A$4="1ª", 'U8'!K5*'U8'!K$4, 0) + IF('U9'!$A$4="1ª", 'U9'!K5*'U9'!K$4, 0) + IF('U10'!$A$4="1ª", 'U10'!K5*'U10'!K$4, 0) + IF('U11'!$A$4="1ª", 'U11'!K5*'U11'!K$4, 0) + IF('U12'!$A$4="1ª", 'U12'!K5*'U12'!K$4, 0) + IF('U13'!$A$4="1ª", 'U13'!K5*'U13'!K$4, 0) + IF('U14'!$A$4="1ª", 'U14'!K5*'U14'!K$4, 0) + IF('U15'!$A$4="1ª", 'U15'!K5*'U15'!K$4, 0) ) /$CB$12 ) /V$13, "") -> 0 | X19: =IF(X$13>0, ( ( IF('U1'!$A$4="1ª", 'U1'!L5*'U1'!L$4, 0) + IF('U2'!$A$4="1ª", 'U2'!L5*'U2'!L$4, 0) + IF('U3'!$A$4="1ª", 'U3'!L5*'U3'!L$4, 0) + IF('U4'!$A$4="1ª", 'U4'!L5*'U4'!L$4, 0) + IF('U5'!$A$4="1ª", 'U5'!L5*'U5'!L$4, 0) + IF('U6'!$A$4="1ª", 'U6'!L5*'U6'!L$4, 0) + IF('U7'!$A$4="1ª", 'U7'!L5*'U7'!L$4, 0) + IF('U8'!$A$4="1ª", 'U8'!L5*'U8'!L$4, 0) + IF('U9'!$A$4="1ª", 'U9'!L5*'U9'!L$4, 0) + IF('U10'!$A$4="1ª", 'U10'!L5*'U10'!L$4, 0) + IF('U11'!$A$4="1ª", 'U11'!L5*'U11'!L$4, 0) + IF('U12'!$A$4="1ª", 'U12'!L5*'U12'!L$4, 0) + IF('U13'!$A$4="1ª", 'U13'!L5*'U13'!L$4, 0) + IF('U14'!$A$4="1ª", 'U14'!L5*'U14'!L$4, 0) + IF('U15'!$A$4="1ª", 'U15'!L5*'U15'!L$4, 0) ) /$CB$12 ) /X$13, "") | Z19: =IF(Z$13>0, ( ( IF('U1'!$A$4="1ª", 'U1'!M5*'U1'!M$4, 0) + IF('U2'!$A$4="1ª", 'U2'!M5*'U2'!M$4, 0) + IF('U3'!$A$4="1ª", 'U3'!M5*'U3'!M$4, 0) + IF('U4'!$A$4="1ª", 'U4'!M5*'U4'!M$4, 0) + IF('U5'!$A$4="1ª", 'U5'!M5*'U5'!M$4, 0) + IF('U6'!$A$4="1ª", 'U6'!M5*'U6'!M$4, 0) + IF('U7'!$A$4="1ª", 'U7'!M5*'U7'!M$4, 0) + IF('U8'!$A$4="1ª", 'U8'!M5*'U8'!M$4, 0) + IF('U9'!$A$4="1ª", 'U9'!M5*'U9'!M$4, 0) + IF('U10'!$A$4="1ª", 'U10'!M5*'U10'!M$4, 0) + IF('U11'!$A$4="1ª", 'U11'!M5*'U11'!M$4, 0) + IF('U12'!$A$4="1ª", 'U12'!M5*'U12'!M$4, 0) + IF('U13'!$A$4="1ª", 'U13'!M5*'U13'!M$4, 0) + IF('U14'!$A$4="1ª", 'U14'!M5*'U14'!M$4, 0) + IF('U15'!$A$4="1ª", 'U15'!M5*'U15'!M$4, 0) ) /$CB$12 ) /Z$13, "") | AB19: =IFERROR(SUM( MAX(AC19,AD19)*AC$13, MAX(AE19,AF19)*AE$13, MAX(AG19,AH19)*AG$13, MAX(AI19,AJ19)*AI$13, MAX(AK19,AL19)*AK$13, MAX(AM19,AN19)*AM$13 )/AB$14,"") -> 0 | AC19: =IF(AC$13>0, ( ( IF('U1'!$A$4="1ª", 'U1'!N5*'U1'!N$4, 0) + IF('U2'!$A$4="1ª", 'U2'!N5*'U2'!N$4, 0) + IF('U3'!$A$4="1ª", 'U3'!N5*'U3'!N$4, 0) + IF('U4'!$A$4="1ª", 'U4'!N5*'U4'!N$4, 0) + IF('U5'!$A$4="1ª", 'U5'!N5*'U5'!N$4, 0) + IF('U6'!$A$4="1ª", 'U6'!N5*'U6'!N$4, 0) + IF('U7'!$A$4="1ª", 'U7'!N5*'U7'!N$4, 0) + IF('U8'!$A$4="1ª", 'U8'!N5*'U8'!N$4, 0) + IF('U9'!$A$4="1ª", 'U9'!N5*'U9'!N$4, 0) + IF('U10'!$A$4="1ª", 'U10'!N5*'U10'!N$4, 0) + IF('U11'!$A$4="1ª", 'U11'!N5*'U11'!N$4, 0) + IF('U12'!$A$4="1ª", 'U12'!N5*'U12'!N$4, 0) + IF('U13'!$A$4="1ª", 'U13'!N5*'U13'!N$4, 0) + IF('U14'!$A$4="1ª", 'U14'!N5*'U14'!N$4, 0) + IF('U15'!$A$4="1ª", 'U15'!N5*'U15'!N$4, 0) ) /$CB$12 ) /AC$13, "") | AE19: =IF(AE$13>0, ( ( IF('U1'!$A$4="1ª", 'U1'!O5*'U1'!O$4, 0)+ IF('U2'!$A$4="1ª", 'U2'!O5*'U2'!O$4, 0)+ IF('U3'!$A$4="1ª", 'U3'!O5*'U3'!O$4, 0)+ IF('U4'!$A$4="1ª", 'U4'!O5*'U4'!O$4, 0)+ IF('U5'!$A$4="1ª", 'U5'!O5*'U5'!O$4, 0)+ IF('U6'!$A$4="1ª", 'U6'!O5*'U6'!O$4, 0)+ IF('U7'!$A$4="1ª", 'U7'!O5*'U7'!O$4, 0)+ IF('U8'!$A$4="1ª", 'U8'!O5*'U8'!O$4, 0)+ IF('U9'!$A$4="1ª", 'U9'!O5*'U9'!O$4, 0)+ IF('U10'!$A$4="1ª", 'U10'!O5*'U10'!O$4, 0)+ IF('U11'!$A$4="1ª", 'U11'!O5*'U11'!O$4, 0)+ IF('U12'!$A$4="1ª", 'U12'!O5*'U12'!O$4, 0)+ IF('U13'!$A$4="1ª", 'U13'!O5*'U13'!O$4, 0)+ IF('U14'!$A$4="1ª", 'U14'!O5*'U14'!O$4, 0)+ IF('U15'!$A$4="1ª", 'U15'!O5*'U15'!O$4, 0) ) /$CB$12 ) /AE$13, "") | AG19: =IF(AG$13>0, ( ( IF('U1'!$A$4="1ª", 'U1'!P5*'U1'!P$4, 0)+ IF('U2'!$A$4="1ª", 'U2'!P5*'U2'!P$4, 0)+ IF('U3'!$A$4="1ª", 'U3'!P5*'U3'!P$4, 0)+ IF('U4'!$A$4="1ª", 'U4'!P5*'U4'!P$4, 0)+ IF('U5'!$A$4="1ª", 'U5'!P5*'U5'!P$4, 0)+ IF('U6'!$A$4="1ª", 'U6'!P5*'U6'!P$4, 0)+ IF('U7'!$A$4="1ª", 'U7'!P5*'U7'!P$4, 0)+ IF('U8'!$A$4="1ª", 'U8'!P5*'U8'!P$4, 0)+ IF('U9'!$A$4="1ª", 'U9'!P5*'U9'!P$4, 0)+ IF('U10'!$A$4="1ª", 'U10'!P5*'U10'!P$4, 0)+ IF('U11'!$A$4="1ª", 'U11'!P5*'U11'!P$4, 0)+ IF('U12'!$A$4="1ª", 'U12'!P5*'U12'!P$4, 0)+ IF('U13'!$A$4="1ª", 'U13'!P5*'U13'!P$4, 0)+ IF('U14'!$A$4="1ª", 'U14'!P5*'U14'!P$4, 0)+ IF('U15'!$A$4="1ª", 'U15'!P5*'U15'!P$4, 0) ) /$CB$12 ) /AG$13, "") | AI19: =IF(AI$13>0, ( ( IF('U1'!$A$4="1ª", 'U1'!Q5*'U1'!Q$4, 0)+ IF('U2'!$A$4="1ª", 'U2'!Q5*'U2'!Q$4, 0)+ IF('U3'!$A$4="1ª", 'U3'!Q5*'U3'!Q$4, 0)+ IF('U4'!$A$4="1ª", 'U4'!Q5*'U4'!Q$4, 0)+ IF('U5'!$A$4="1ª", 'U5'!Q5*'U5'!Q$4, 0)+ IF('U6'!$A$4="1ª", 'U6'!Q5*'U6'!Q$4, 0)+ IF('U7'!$A$4="1ª", 'U7'!Q5*'U7'!Q$4, 0)+ IF('U8'!$A$4="1ª", 'U8'!Q5*'U8'!Q$4, 0)+ IF('U9'!$A$4="1ª", 'U9'!Q5*'U9'!Q$4, 0)+ IF('U10'!$A$4="1ª", 'U10'!Q5*'U10'!Q$4, 0)+ IF('U11'!$A$4="1ª", 'U11'!Q5*'U11'!Q$4, 0)+ IF('U12'!$A$4="1ª", 'U12'!Q5*'U12'!Q$4, 0)+ IF('U13'!$A$4="1ª", 'U13'!Q5*'U13'!Q$4, 0)+ IF('U14'!$A$4="1ª", 'U14'!Q5*'U14'!Q$4, 0)+ IF('U15'!$A$4="1ª", 'U15'!Q5*'U15'!Q$4, 0) ) /$CB$12 ) /AI$13, "") -> 0 | AK19: =IF(AK$13>0, ( ( IF('U1'!$A$4="1ª", 'U1'!R5*'U1'!R$4, 0)+ IF('U2'!$A$4="1ª", 'U2'!R5*'U2'!R$4, 0)+ IF('U3'!$A$4="1ª", 'U3'!R5*'U3'!R$4, 0)+ IF('U4'!$A$4="1ª", 'U4'!R5*'U4'!R$4, 0)+ IF('U5'!$A$4="1ª", 'U5'!R5*'U5'!R$4, 0)+ IF('U6'!$A$4="1ª", 'U6'!R5*'U6'!R$4, 0)+ IF('U7'!$A$4="1ª", 'U7'!R5*'U7'!R$4, 0)+ IF('U8'!$A$4="1ª", 'U8'!R5*'U8'!R$4, 0)+ IF('U9'!$A$4="1ª", 'U9'!R5*'U9'!R$4, 0)+ IF('U10'!$A$4="1ª", 'U10'!R5*'U10'!R$4, 0)+ IF('U11'!$A$4="1ª", 'U11'!R5*'U11'!R$4, 0)+ IF('U12'!$A$4="1ª", 'U12'!R5*'U12'!R$4, 0)+ IF('U13'!$A$4="1ª", 'U13'!R5*'U13'!R$4, 0)+ IF('U14'!$A$4="1ª", 'U14'!R5*'U14'!R$4, 0)+ IF('U15'!$A$4="1ª", 'U15'!R5*'U15'!R$4, 0) ) /$CB$12 ) /AK$13, "") -> 0 | AM19: =IF(AM$13>0, ( ( IF('U1'!$A$4="1ª", 'U1'!S5*'U1'!S$4, 0)+ IF('U2'!$A$4="1ª", 'U2'!S5*'U2'!S$4, 0)+ IF('U3'!$A$4="1ª", 'U3'!S5*'U3'!S$4, 0)+ IF('U4'!$A$4="1ª", 'U4'!S5*'U4'!S$4, 0)+ IF('U5'!$A$4="1ª", 'U5'!S5*'U5'!S$4, 0)+ IF('U6'!$A$4="1ª", 'U6'!S5*'U6'!S$4, 0)+ IF('U7'!$A$4="1ª", 'U7'!S5*'U7'!S$4, 0)+ IF('U8'!$A$4="1ª", 'U8'!S5*'U8'!S$4, 0)+ IF('U9'!$A$4="1ª", 'U9'!S5*'U9'!S$4, 0)+ IF('U10'!$A$4="1ª", 'U10'!S5*'U10'!S$4, 0)+ IF('U11'!$A$4="1ª", 'U11'!S5*'U11'!S$4, 0)+ IF('U12'!$A$4="1ª", 'U12'!S5*'U12'!S$4, 0)+ IF('U13'!$A$4="1ª", 'U13'!S5*'U13'!S$4, 0)+ IF('U14'!$A$4="1ª", 'U14'!S5*'U14'!S$4, 0)+ IF('U15'!$A$4="1ª", 'U15'!S5*'U15'!S$4, 0) ) /$CB$12 ) /AM$13, "") | AO19: =IFERROR(SUM( MAX(AP19,AQ19)*AP$13, MAX(AR19,AS19)*AR$13, MAX(AT19,AU19)*AT$13, MAX(AV19,AW19)*AV$13, MAX(AX19,AY19)*AX$13, MAX(AZ19,BA19)*AZ$13 )/AO$14,"") -> 0 | AP19: =IF(AP$13>0, ( ( IF('U1'!$A$4="1ª", 'U1'!T5*'U1'!T$4, 0)+ IF('U2'!$A$4="1ª", 'U2'!T5*'U2'!T$4, 0)+ IF('U3'!$A$4="1ª", 'U3'!T5*'U3'!T$4, 0)+ IF('U4'!$A$4="1ª", 'U4'!T5*'U4'!T$4, 0)+ IF('U5'!$A$4="1ª", 'U5'!T5*'U5'!T$4, 0)+ IF('U6'!$A$4="1ª", 'U6'!T5*'U6'!T$4, 0)+ IF('U7'!$A$4="1ª", 'U7'!T5*'U7'!T$4, 0)+ IF('U8'!$A$4="1ª", 'U8'!T5*'U8'!T$4, 0)+ IF('U9'!$A$4="1ª", 'U9'!T5*'U9'!T$4, 0)+ IF('U10'!$A$4="1ª", 'U10'!T5*'U10'!T$4, 0)+ IF('U11'!$A$4="1ª", 'U11'!T5*'U11'!T$4, 0)+ IF('U12'!$A$4="1ª", 'U12'!T5*'U12'!T$4, 0)+ IF('U13'!$A$4="1ª", 'U13'!T5*'U13'!T$4, 0)+ IF('U14'!$A$4="1ª", 'U14'!T5*'U14'!T$4, 0)+ IF('U15'!$A$4="1ª", 'U15'!T5*'U15'!T$4, 0) ) /$CB$12 ) /AP$13, "") -> 0 | AR19: =IF(AR$13>0, ( ( IF('U1'!$A$4="1ª", 'U1'!U5*'U1'!U$4, 0)+ IF('U2'!$A$4="1ª", 'U2'!U5*'U2'!U$4, 0)+ IF('U3'!$A$4="1ª", 'U3'!U5*'U3'!U$4, 0)+ IF('U4'!$A$4="1ª", 'U4'!U5*'U4'!U$4, 0)+ IF('U5'!$A$4="1ª", 'U5'!U5*'U5'!U$4, 0)+ IF('U6'!$A$4="1ª", 'U6'!U5*'U6'!U$4, 0)+ IF('U7'!$A$4="1ª", 'U7'!U5*'U7'!U$4, 0)+ IF('U8'!$A$4="1ª", 'U8'!U5*'U8'!U$4, 0)+ IF('U9'!$A$4="1ª", 'U9'!U5*'U9'!U$4, 0)+ IF('U10'!$A$4="1ª", 'U10'!U5*'U10'!U$4, 0)+ IF('U11'!$A$4="1ª", 'U11'!U5*'U11'!U$4, 0)+ IF('U12'!$A$4="1ª", 'U12'!U5*'U12'!U$4, 0)+ IF('U13'!$A$4="1ª", 'U13'!U5*'U13'!U$4, 0)+ IF('U14'!$A$4="1ª", 'U14'!U5*'U14'!U$4, 0)+ IF('U15'!$A$4="1ª", 'U15'!U5*'U15'!U$4, 0) ) /$CB$12 ) /AR$13, "") -> 0 | AT19: =IF(AT$13>0, ( ( IF('U1'!$A$4="1ª", 'U1'!V5*'U1'!V$4, 0)+ IF('U2'!$A$4="1ª", 'U2'!V5*'U2'!V$4, 0)+ IF('U3'!$A$4="1ª", 'U3'!V5*'U3'!V$4, 0)+ IF('U4'!$A$4="1ª", 'U4'!V5*'U4'!V$4, 0)+ IF('U5'!$A$4="1ª", 'U5'!V5*'U5'!V$4, 0)+ IF('U6'!$A$4="1ª", 'U6'!V5*'U6'!V$4, 0)+ IF('U7'!$A$4="1ª", 'U7'!V5*'U7'!V$4, 0)+ IF('U8'!$A$4="1ª", 'U8'!V5*'U8'!V$4, 0)+ IF('U9'!$A$4="1ª", 'U9'!V5*'U9'!V$4, 0)+ IF('U10'!$A$4="1ª", 'U10'!V5*'U10'!V$4, 0)+ IF('U11'!$A$4="1ª", 'U11'!V5*'U11'!V$4, 0)+ IF('U12'!$A$4="1ª", 'U12'!V5*'U12'!V$4, 0)+ IF('U13'!$A$4="1ª", 'U13'!V5*'U13'!V$4, 0)+ IF('U14'!$A$4="1ª", 'U14'!V5*'U14'!V$4, 0)+ IF('U15'!$A$4="1ª", 'U15'!V5*'U15'!V$4, 0) ) /$CB$12 ) /AT$13, "") | AV19: =IF(AV$13>0, ( ( IF('U1'!$A$4="1ª", 'U1'!W5*'U1'!W$4, 0)+ IF('U2'!$A$4="1ª", 'U2'!W5*'U2'!W$4, 0)+ IF('U3'!$A$4="1ª", 'U3'!W5*'U3'!W$4, 0)+ IF('U4'!$A$4="1ª", 'U4'!W5*'U4'!W$4, 0)+ IF('U5'!$A$4="1ª", 'U5'!W5*'U5'!W$4, 0)+ IF('U6'!$A$4="1ª", 'U6'!W5*'U6'!W$4, 0)+ IF('U7'!$A$4="1ª", 'U7'!W5*'U7'!W$4, 0)+ IF('U8'!$A$4="1ª", 'U8'!W5*'U8'!W$4, 0)+ IF('U9'!$A$4="1ª", 'U9'!W5*'U9'!W$4, 0)+ IF('U10'!$A$4="1ª", 'U10'!W5*'U10'!W$4, 0)+ IF('U11'!$A$4="1ª", 'U11'!W5*'U11'!W$4, 0)+ IF('U12'!$A$4="1ª", 'U12'!W5*'U12'!W$4, 0)+ IF('U13'!$A$4="1ª", 'U13'!W5*'U13'!W$4, 0)+ IF('U14'!$A$4="1ª", 'U14'!W5*'U14'!W$4, 0)+ IF('U15'!$A$4="1ª", 'U15'!W5*'U15'!W$4, 0) ) /$CB$12 ) /AV$13, "") -> 0 | AX19: =IF(AX$13>0, ( ( IF('U1'!$A$4="1ª", 'U1'!X5*'U1'!X$4, 0)+ IF('U2'!$A$4="1ª", 'U2'!X5*'U2'!X$4, 0)+ IF('U3'!$A$4="1ª", 'U3'!X5*'U3'!X$4, 0)+ IF('U4'!$A$4="1ª", 'U4'!X5*'U4'!X$4, 0)+ IF('U5'!$A$4="1ª", 'U5'!X5*'U5'!X$4, 0)+ IF('U6'!$A$4="1ª", 'U6'!X5*'U6'!X$4, 0)+ IF('U7'!$A$4="1ª", 'U7'!X5*'U7'!X$4, 0)+ IF('U8'!$A$4="1ª", 'U8'!X5*'U8'!X$4, 0)+ IF('U9'!$A$4="1ª", 'U9'!X5*'U9'!X$4, 0)+ IF('U10'!$A$4="1ª", 'U10'!X5*'U10'!X$4, 0)+ IF('U11'!$A$4="1ª", 'U11'!X5*'U11'!X$4, 0)+ IF('U12'!$A$4="1ª", 'U12'!X5*'U12'!X$4, 0)+ IF('U13'!$A$4="1ª", 'U13'!X5*'U13'!X$4, 0)+ IF('U14'!$A$4="1ª", 'U14'!X5*'U14'!X$4, 0)+ IF('U15'!$A$4="1ª", 'U15'!X5*'U15'!X$4, 0) ) /$CB$12 ) /AX$13, "") | AZ19: =IF(AZ$13>0, ( ( IF('U1'!$A$4="1ª", 'U1'!Y5*'U1'!Y$4, 0)+ IF('U2'!$A$4="1ª", 'U2'!Y5*'U2'!Y$4, 0)+ IF('U3'!$A$4="1ª", 'U3'!Y5*'U3'!Y$4, 0)+ IF('U4'!$A$4="1ª", 'U4'!Y5*'U4'!Y$4, 0)+ IF('U5'!$A$4="1ª", 'U5'!Y5*'U5'!Y$4, 0)+ IF('U6'!$A$4="1ª", 'U6'!Y5*'U6'!Y$4, 0)+ IF('U7'!$A$4="1ª", 'U7'!Y5*'U7'!Y$4, 0)+ IF('U8'!$A$4="1ª", 'U8'!Y5*'U8'!Y$4, 0)+ IF('U9'!$A$4="1ª", 'U9'!Y5*'U9'!Y$4, 0)+ IF('U10'!$A$4="1ª", 'U10'!Y5*'U10'!Y$4, 0)+ IF('U11'!$A$4="1ª", 'U11'!Y5*'U11'!Y$4, 0)+ IF('U12'!$A$4="1ª", 'U12'!Y5*'U12'!Y$4, 0)+ IF('U13'!$A$4="1ª", 'U13'!Y5*'U13'!Y$4, 0)+ IF('U14'!$A$4="1ª", 'U14'!Y5*'U14'!Y$4, 0)+ IF('U15'!$A$4="1ª", 'U15'!Y5*'U15'!Y$4, 0) ) /$CB$12 ) /AZ$13, "") | BB19: =IFERROR(SUM( MAX(BC19,BD19)*BC$13, MAX(BE19,BF19)*BE$13, MAX(BG19,BH19)*BG$13, MAX(BI19,BJ19)*BI$13, MAX(BK19,BL19)*BK$13, MAX(BM19,BN19)*BM$13 )/BB$14,"") -> 0 | BC19: =IF(BC$13>0, ( ( IF('U1'!$A$4="1ª", 'U1'!Z5*'U1'!Z$4, 0)+ IF('U2'!$A$4="1ª", 'U2'!Z5*'U2'!Z$4, 0)+ IF('U3'!$A$4="1ª", 'U3'!Z5*'U3'!Z$4, 0)+ IF('U4'!$A$4="1ª", 'U4'!Z5*'U4'!Z$4, 0)+ IF('U5'!$A$4="1ª", 'U5'!Z5*'U5'!Z$4, 0)+ IF('U6'!$A$4="1ª", 'U6'!Z5*'U6'!Z$4, 0)+ IF('U7'!$A$4="1ª", 'U7'!Z5*'U7'!Z$4, 0)+ IF('U8'!$A$4="1ª", 'U8'!Z5*'U8'!Z$4, 0)+ IF('U9'!$A$4="1ª", 'U9'!Z5*'U9'!Z$4, 0)+ IF('U10'!$A$4="1ª", 'U10'!Z5*'U10'!Z$4, 0)+ IF('U11'!$A$4="1ª", 'U11'!Z5*'U11'!Z$4, 0)+ IF('U12'!$A$4="1ª", 'U12'!Z5*'U12'!Z$4, 0)+ IF('U13'!$A$4="1ª", 'U13'!Z5*'U13'!Z$4, 0)+ IF('U14'!$A$4="1ª", 'U14'!Z5*'U14'!Z$4, 0)+ IF('U15'!$A$4="1ª", 'U15'!Z5*'U15'!Z$4, 0) ) /$CB$12 ) /BC$13, "") | BE19: =IF(BE$13>0, ( ( IF('U1'!$A$4="1ª", 'U1'!AA5*'U1'!AA$4, 0)+ IF('U2'!$A$4="1ª", 'U2'!AA5*'U2'!AA$4, 0)+ IF('U3'!$A$4="1ª", 'U3'!AA5*'U3'!AA$4, 0)+ IF('U4'!$A$4="1ª", 'U4'!AA5*'U4'!AA$4, 0)+ IF('U5'!$A$4="1ª", 'U5'!AA5*'U5'!AA$4, 0)+ IF('U6'!$A$4="1ª", 'U6'!AA5*'U6'!AA$4, 0)+ IF('U7'!$A$4="1ª", 'U7'!AA5*'U7'!AA$4, 0)+ IF('U8'!$A$4="1ª", 'U8'!AA5*'U8'!AA$4, 0)+ IF('U9'!$A$4="1ª", 'U9'!AA5*'U9'!AA$4, 0)+ IF('U10'!$A$4="1ª", 'U10'!AA5*'U10'!AA$4, 0)+ IF('U11'!$A$4="1ª", 'U11'!AA5*'U11'!AA$4, 0)+ IF('U12'!$A$4="1ª", 'U12'!AA5*'U12'!AA$4, 0)+ IF('U13'!$A$4="1ª", 'U13'!AA5*'U13'!AA$4, 0)+ IF('U14'!$A$4="1ª", 'U14'!AA5*'U14'!AA$4, 0)+ IF('U15'!$A$4="1ª", 'U15'!AA5*'U15'!AA$4, 0) ) /$CB$12 ) /BE$13, "") | BG19: =IF(BG$13>0, ( ( IF('U1'!$A$4="1ª", 'U1'!AB5*'U1'!AB$4, 0)+ IF('U2'!$A$4="1ª", 'U2'!AB5*'U2'!AB$4, 0)+ IF('U3'!$A$4="1ª", 'U3'!AB5*'U3'!AB$4, 0)+ IF('U4'!$A$4="1ª", 'U4'!AB5*'U4'!AB$4, 0)+ IF('U5'!$A$4="1ª", 'U5'!AB5*'U5'!AB$4, 0)+ IF('U6'!$A$4="1ª", 'U6'!AB5*'U6'!AB$4, 0)+ IF('U7'!$A$4="1ª", 'U7'!AB5*'U7'!AB$4, 0)+ IF('U8'!$A$4="1ª", 'U8'!AB5*'U8'!AB$4, 0)+ IF('U9'!$A$4="1ª", 'U9'!AB5*'U9'!AB$4, 0)+ IF('U10'!$A$4="1ª", 'U10'!AB5*'U10'!AB$4, 0)+ IF('U11'!$A$4="1ª", 'U11'!AB5*'U11'!AB$4, 0)+ IF('U12'!$A$4="1ª", 'U12'!AB5*'U12'!AB$4, 0)+ IF('U13'!$A$4="1ª", 'U13'!AB5*'U13'!AB$4, 0)+ IF('U14'!$A$4="1ª", 'U14'!AB5*'U14'!AB$4, 0)+ IF('U15'!$A$4="1ª", 'U15'!AB5*'U15'!AB$4, 0) ) /$CB$12 ) /BG$13, "") | BI19: =IF(BI$13>0, ( ( IF('U1'!$A$4="1ª", 'U1'!AC5*'U1'!AC$4, 0)+ IF('U2'!$A$4="1ª", 'U2'!AC5*'U2'!AC$4, 0)+ IF('U3'!$A$4="1ª", 'U3'!AC5*'U3'!AC$4, 0)+ IF('U4'!$A$4="1ª", 'U4'!AC5*'U4'!AC$4, 0)+ IF('U5'!$A$4="1ª", 'U5'!AC5*'U5'!AC$4, 0)+ IF('U6'!$A$4="1ª", 'U6'!AC5*'U6'!AC$4, 0)+ IF('U7'!$A$4="1ª", 'U7'!AC5*'U7'!AC$4, 0)+ IF('U8'!$A$4="1ª", 'U8'!AC5*'U8'!AC$4, 0)+ IF('U9'!$A$4="1ª", 'U9'!AC5*'U9'!AC$4, 0)+ IF('U10'!$A$4="1ª", 'U10'!AC5*'U10'!AC$4, 0)+ IF('U11'!$A$4="1ª", 'U11'!AC5*'U11'!AC$4, 0)+ IF('U12'!$A$4="1ª", 'U12'!AC5*'U12'!AC$4, 0)+ IF('U13'!$A$4="1ª", 'U13'!AC5*'U13'!AC$4, 0)+ IF('U14'!$A$4="1ª", 'U14'!AC5*'U14'!AC$4, 0)+ IF('U15'!$A$4="1ª", 'U15'!AC5*'U15'!AC$4, 0) ) /$CB$12 ) /BI$13, "") -> 0 | BK19: =IF(BK$13>0, ( ( IF('U1'!$A$4="1ª", 'U1'!AD5*'U1'!AD$4, 0)+ IF('U2'!$A$4="1ª", 'U2'!AD5*'U2'!AD$4, 0)+ IF('U3'!$A$4="1ª", 'U3'!AD5*'U3'!AD$4, 0)+ IF('U4'!$A$4="1ª", 'U4'!AD5*'U4'!AD$4, 0)+ IF('U5'!$A$4="1ª", 'U5'!AD5*'U5'!AD$4, 0)+ IF('U6'!$A$4="1ª", 'U6'!AD5*'U6'!AD$4, 0)+ IF('U7'!$A$4="1ª", 'U7'!AD5*'U7'!AD$4, 0)+ IF('U8'!$A$4="1ª", 'U8'!AD5*'U8'!AD$4, 0)+ IF('U9'!$A$4="1ª", 'U9'!AD5*'U9'!AD$4, 0)+ IF('U10'!$A$4="1ª", 'U10'!AD5*'U10'!AD$4, 0)+ IF('U11'!$A$4="1ª", 'U11'!AD5*'U11'!AD$4, 0)+ IF('U12'!$A$4="1ª", 'U12'!AD5*'U12'!AD$4, 0)+ IF('U13'!$A$4="1ª", 'U13'!AD5*'U13'!AD$4, 0)+ IF('U14'!$A$4="1ª", 'U14'!AD5*'U14'!AD$4, 0)+ IF('U15'!$A$4="1ª", 'U15'!AD5*'U15'!AD$4, 0) ) /$CB$12 ) /BK$13, "") | BM19: =IF(BM$13>0, ( ( IF('U1'!$A$4="1ª", 'U1'!AE5*'U1'!AE$4, 0)+ IF('U2'!$A$4="1ª", 'U2'!AE5*'U2'!AE$4, 0)+ IF('U3'!$A$4="1ª", 'U3'!AE5*'U3'!AE$4, 0)+ IF('U4'!$A$4="1ª", 'U4'!AE5*'U4'!AE$4, 0)+ IF('U5'!$A$4="1ª", 'U5'!AE5*'U5'!AE$4, 0)+ IF('U6'!$A$4="1ª", 'U6'!AE5*'U6'!AE$4, 0)+ IF('U7'!$A$4="1ª", 'U7'!AE5*'U7'!AE$4, 0)+ IF('U8'!$A$4="1ª", 'U8'!AE5*'U8'!AE$4, 0)+ IF('U9'!$A$4="1ª", 'U9'!AE5*'U9'!AE$4, 0)+ IF('U10'!$A$4="1ª", 'U10'!AE5*'U10'!AE$4, 0)+ IF('U11'!$A$4="1ª", 'U11'!AE5*'U11'!AE$4, 0)+ IF('U12'!$A$4="1ª", 'U12'!AE5*'U12'!AE$4, 0)+ IF('U13'!$A$4="1ª", 'U13'!AE5*'U13'!AE$4, 0)+ IF('U14'!$A$4="1ª", 'U14'!AE5*'U14'!AE$4, 0)+ IF('U15'!$A$4="1ª", 'U15'!AE5*'U15'!AE$4, 0) ) /$CB$12 ) /BM$13, "") | BO19: =IFERROR(SUM( MAX(BP19,BQ19)*BP$13, MAX(BR19,BS19)*BR$13, MAX(BT19,BU19)*BT$13, MAX(BV19,BW19)*BV$13, MAX(BX19,BY19)*BX$13, MAX(BZ19,CA19)*BZ$13 )/BO$14,"") | BP19: =IF(BP$13>0, ( ( IF('U1'!$A$4="1ª", 'U1'!AF5*'U1'!AF$4, 0)+ IF('U2'!$A$4="1ª", 'U2'!AF5*'U2'!AF$4, 0)+ IF('U3'!$A$4="1ª", 'U3'!AF5*'U3'!AF$4, 0)+ IF('U4'!$A$4="1ª", 'U4'!AF5*'U4'!AF$4, 0)+ IF('U5'!$A$4="1ª", 'U5'!AF5*'U5'!AF$4, 0)+ IF('U6'!$A$4="1ª", 'U6'!AF5*'U6'!AF$4, 0)+ IF('U7'!$A$4="1ª", 'U7'!AF5*'U7'!AF$4, 0)+ IF('U8'!$A$4="1ª", 'U8'!AF5*'U8'!AF$4, 0)+ IF('U9'!$A$4="1ª", 'U9'!AF5*'U9'!AF$4, 0)+ IF('U10'!$A$4="1ª", 'U10'!AF5*'U10'!AF$4, 0)+ IF('U11'!$A$4="1ª", 'U11'!AF5*'U11'!AF$4, 0)+ IF('U12'!$A$4="1ª", 'U12'!AF5*'U12'!AF$4, 0)+ IF('U13'!$A$4="1ª", 'U13'!AF5*'U13'!AF$4, 0)+ IF('U14'!$A$4="1ª", 'U14'!AF5*'U14'!AF$4, 0)+ IF('U15'!$A$4="1ª", 'U15'!AF5*'U15'!AF$4, 0) ) /$CB$12 ) /BP$13, "") | BR19: =IF(BR$13>0, ( ( IF('U1'!$A$4="1ª", 'U1'!AG5*'U1'!AG$4, 0)+ IF('U2'!$A$4="1ª", 'U2'!AG5*'U2'!AG$4, 0)+ IF('U3'!$A$4="1ª", 'U3'!AG5*'U3'!AG$4, 0)+ IF('U4'!$A$4="1ª", 'U4'!AG5*'U4'!AG$4, 0)+ IF('U5'!$A$4="1ª", 'U5'!AG5*'U5'!AG$4, 0)+ IF('U6'!$A$4="1ª", 'U6'!AG5*'U6'!AG$4, 0)+ IF('U7'!$A$4="1ª", 'U7'!AG5*'U7'!AG$4, 0)+ IF('U8'!$A$4="1ª", 'U8'!AG5*'U8'!AG$4, 0)+ IF('U9'!$A$4="1ª", 'U9'!AG5*'U9'!AG$4, 0)+ IF('U10'!$A$4="1ª", 'U10'!AG5*'U10'!AG$4, 0)+ IF('U11'!$A$4="1ª", 'U11'!AG5*'U11'!AG$4, 0)+ IF('U12'!$A$4="1ª", 'U12'!AG5*'U12'!AG$4, 0)+ IF('U13'!$A$4="1ª", 'U13'!AG5*'U13'!AG$4, 0)+ IF('U14'!$A$4="1ª", 'U14'!AG5*'U14'!AG$4, 0)+ IF('U15'!$A$4="1ª", 'U15'!AG5*'U15'!AG$4, 0) ) /$CB$12 ) /BR$13, "") | BT19: =IF(BT$13>0, ( ( IF('U1'!$A$4="1ª", 'U1'!AH5*'U1'!AH$4, 0)+ IF('U2'!$A$4="1ª", 'U2'!AH5*'U2'!AH$4, 0)+ IF('U3'!$A$4="1ª", 'U3'!AH5*'U3'!AH$4, 0)+ IF('U4'!$A$4="1ª", 'U4'!AH5*'U4'!AH$4, 0)+ IF('U5'!$A$4="1ª", 'U5'!AH5*'U5'!AH$4, 0)+ IF('U6'!$A$4="1ª", 'U6'!AH5*'U6'!AH$4, 0)+ IF('U7'!$A$4="1ª", 'U7'!AH5*'U7'!AH$4, 0)+ IF('U8'!$A$4="1ª", 'U8'!AH5*'U8'!AH$4, 0)+ IF('U9'!$A$4="1ª", 'U9'!AH5*'U9'!AH$4, 0)+ IF('U10'!$A$4="1ª", 'U10'!AH5*'U10'!AH$4, 0)+ IF('U11'!$A$4="1ª", 'U11'!AH5*'U11'!AH$4, 0)+ IF('U12'!$A$4="1ª", 'U12'!AH5*'U12'!AH$4, 0)+ IF('U13'!$A$4="1ª", 'U13'!AH5*'U13'!AH$4, 0)+ IF('U14'!$A$4="1ª", 'U14'!AH5*'U14'!AH$4, 0)+ IF('U15'!$A$4="1ª", 'U15'!AH5*'U15'!AH$4, 0) ) /$CB$12 ) /BT$13, "") | BV19: =IF(BT$13>0, ( ( IF('U1'!$A$4="1ª", 'U1'!AH5*'U1'!AH$4, 0)+ IF('U2'!$A$4="1ª", 'U2'!AH5*'U2'!AH$4, 0)+ IF('U3'!$A$4="1ª", 'U3'!AH5*'U3'!AH$4, 0)+ IF('U4'!$A$4="1ª", 'U4'!AH5*'U4'!AH$4, 0)+ IF('U5'!$A$4="1ª", 'U5'!AH5*'U5'!AH$4, 0)+ IF('U6'!$A$4="1ª", 'U6'!AH5*'U6'!AH$4, 0)+ IF('U7'!$A$4="1ª", 'U7'!AH5*'U7'!AH$4, 0)+ IF('U8'!$A$4="1ª", 'U8'!AH5*'U8'!AH$4, 0)+ IF('U9'!$A$4="1ª", 'U9'!AH5*'U9'!AH$4, 0)+ IF('U10'!$A$4="1ª", 'U10'!AH5*'U10'!AH$4, 0)+ IF('U11'!$A$4="1ª", 'U11'!AH5*'U11'!AH$4, 0)+ IF('U12'!$A$4="1ª", 'U12'!AH5*'U12'!AH$4, 0)+ IF('U13'!$A$4="1ª", 'U13'!AH5*'U13'!AH$4, 0)+ IF('U14'!$A$4="1ª", 'U14'!AH5*'U14'!AH$4, 0)+ IF('U15'!$A$4="1ª", 'U15'!AH5*'U15'!AH$4, 0) ) /$CB$12 ) /BT$13, "") | BX19: =IF(BV$13>0, ( ( IF('U1'!$A$4="1ª", 'U1'!AI5*'U1'!AI$4, 0)+ IF('U2'!$A$4="1ª", 'U2'!AI5*'U2'!AI$4, 0)+ IF('U3'!$A$4="1ª", 'U3'!AI5*'U3'!AI$4, 0)+ IF('U4'!$A$4="1ª", 'U4'!AI5*'U4'!AI$4, 0)+ IF('U5'!$A$4="1ª", 'U5'!AI5*'U5'!AI$4, 0)+ IF('U6'!$A$4="1ª", 'U6'!AI5*'U6'!AI$4, 0)+ IF('U7'!$A$4="1ª", 'U7'!AI5*'U7'!AI$4, 0)+ IF('U8'!$A$4="1ª", 'U8'!AI5*'U8'!AI$4, 0)+ IF('U9'!$A$4="1ª", 'U9'!AI5*'U9'!AI$4, 0)+ IF('U10'!$A$4="1ª", 'U10'!AI5*'U10'!AI$4, 0)+ IF('U11'!$A$4="1ª", 'U11'!AI5*'U11'!AI$4, 0)+ IF('U12'!$A$4="1ª", 'U12'!AI5*'U12'!AI$4, 0)+ IF('U13'!$A$4="1ª", 'U13'!AI5*'U13'!AI$4, 0)+ IF('U14'!$A$4="1ª", 'U14'!AI5*'U14'!AI$4, 0)+ IF('U15'!$A$4="1ª", 'U15'!AI5*'U15'!AI$4, 0) ) /$CB$12 ) /BV$13, "") | BZ19: =IF(BZ$13>0, ( ( IF('U1'!$A$4="1ª", 'U1'!AK5*'U1'!AK$4, 0)+ IF('U2'!$A$4="1ª", 'U2'!AK5*'U2'!AK$4, 0)+ IF('U3'!$A$4="1ª", 'U3'!AK5*'U3'!AK$4, 0)+ IF('U4'!$A$4="1ª", 'U4'!AK5*'U4'!AK$4, 0)+ IF('U5'!$A$4="1ª", 'U5'!AK5*'U5'!AK$4, 0)+ IF('U6'!$A$4="1ª", 'U6'!AK5*'U6'!AK$4, 0)+ IF('U7'!$A$4="1ª", 'U7'!AK5*'U7'!AK$4, 0)+ IF('U8'!$A$4="1ª", 'U8'!AK5*'U8'!AK$4, 0)+ IF('U9'!$A$4="1ª", 'U9'!AK5*'U9'!AK$4, 0)+ IF('U10'!$A$4="1ª", 'U10'!AK5*'U10'!AK$4, 0)+ IF('U11'!$A$4="1ª", 'U11'!AK5*'U11'!AK$4, 0)+ IF('U12'!$A$4="1ª", 'U12'!AK5*'U12'!AK$4, 0)+ IF('U13'!$A$4="1ª", 'U13'!AK5*'U13'!AK$4, 0)+ IF('U14'!$A$4="1ª", 'U14'!AK5*'U14'!AK$4, 0)+ IF('U15'!$A$4="1ª", 'U15'!AK5*'U15'!AK$4, 0) ) /$CB$12 ) /BZ$13, "") | CB19: =MAX(P19,Q19)*$P$13 +MAX(R19,S19)*$R$13 +MAX(T19,U19)*$T$13 +MAX(V19,W19)*$V$13 +MAX(X19,Y19)*$X$13 +MAX(Z19,AA19)*$Z$13+MAX(C19,D19)*$C$13 +MAX(E19,F19)*$E$13 +MAX(G19,H19)*$G$13 +MAX(I19,J19)*$I$13 +MAX(K19,L19)*$K$13 +MAX(M19,N19)*$M$13+MAX(AC19,AD19)*$AC$13 +MAX(AE19,AF19)*$AE$13 +MAX(AG19,AH19)*$AG$13 +MAX(AI19,AJ19)*$AI$13 +MAX(AK19,AL19)*$AK$13 +MAX(AM19,AN19)*$AM$13+MAX(AP19,AQ19)*$AP$13 +MAX(AR19,AS19)*$AR$13 +MAX(AT19,AU19)*$AT$13 +MAX(AV19,AW19)*$AV$13 +MAX(AX19,AY19)*$AX$13 +MAX(AZ19,BA19)*$AZ$13+MAX(BC19,BD19)*$BC$13 +MAX(BE19,BF19)*$BE$13 +MAX(BG19,BH19)*$BG$13 +MAX(BI19,BJ19)*$BI$13 +MAX(BK19,BL19)*$BK$13 +MAX(BM19,BN19)*$BM$13+MAX(BP19,BQ19)*$BP$13 +MAX(BR19,BS19)*$BR$13 +MAX(BT19,BU19)*$BT$13 +MAX(BV19,BW19)*$BV$13 +MAX(BX19,BY19)*$BX$13 +MAX(BZ19,CA19)*$BZ$13 -> 0 | CC19: =B19*$B$14+O19*$O$14+AB19*$AB$14+AO19*$AO$14+BB19*$BB$14 -> 0
